Workbook

Sheet До рубки 208 1.1
W2: ИНСТРУКЦИЯ | AE2: 8 | AF2: Скопировать итоговые характеристики насаждения "До" и "После" в лист "Расчёты для проекта"
V3: 1 | W3: Скопировать лист внутри книги Excel | AE3: 9 | AF3: Заполнить Проект рубок ухода
V4: 2 | W4: Указать стадию (переименовать лист) "До рубки" | AE4: 10 | AF4: Скопировать данные перечёта по породам в Перечётные ведомости
V5: 3 | W5: Заполнит информацию о делянке (номер ведомости, квартал, выдел и т.д.) | AE5: 11 | AF5: Оформить пакет сопроводительной документация на делянку
V6: 4 | W6: Ввести данные перечёта | AE6: 12 | AF6: Подать уведомление в лесничество
V7: 5 | W7: Скопировать лист "до рубки" внутри книги Excel | AE7: 13 | AF7: Провести рубку
V8: 6 | W8: Указать стадию (переименовать лист) "После рубки" | AE8: 14
V9: 7 | W9: Удалить из ведомости перечёта то, что проектируется удалить в натуре | AE9: 15
N13: Стадия (до, проект или после рубки)
N16: Перечётная ведомость | S16: 1 | U16: Кв | V16: 208 | X16: Выд | Y16: 1.1 | Z16: делянка | AC16: Радиус ПП, м | AE16: 1.78 | AG16: Измерения выполнил: __________________ Дата, подпись, расшифровка _________________________
B18: Костыль для высоты | N18: Пор. | O18: Площадка | S18: Сосна | Y18: Ель из подроста | AE18: ЕЛЬ лесные культуры | AK18: Берёза | AO18: Осина | AS18: Ольха серая | AW18: Ива | BA18: Чёрёмуха | BE18: Дуб | BI18: Рябина
B19: =Y18 | C19: =AE18 | D19: =S18 | E19: =AK18 | F19: =AO18 | G19: =AS18 | H19: =AW18 | I19: =BA18 | J19: =BE18 | K19: =BI18 | L19: Всего, тыс.шт/га | N19: NN | O19: GPS точка | P19: ТЛ/ТУМ | Q19: Предмет ухода | R19: примечание | S19: До 0.5м | T19: 0,5-1,5 | U19: > 1.5 | V19: D, см | W19: h, м | X19: A, лет | Y19: До 0.5м | Z19: 0,5-1,5 | AA19: > 1.5 | AB19: D, см | AC19: h, м | AD19: A, лет | AE19: До 0.5м | AF19: 0,5-1,5 | AG19: > 1.5 | AH19: D, см | AI19: h, м | AJ19: A, лет | AK19: Кол-во | AL19: D, см | AM19: h, м | AN19: A, лет | AO19: Кол-во | AP19: D, см | AQ19: h, м | AR19: A, лет | AS19: Кол-во | AT19: D, см | AU19: h, м | AV19: A, лет | AW19: Кол-во | AX19: D, см | AY19: h, м | AZ19: A, лет | BA19: Кол-во | BB19: D, см | BC19: h, м | BD19: A, лет | BE19: Кол-во | BF19: D, см | BG19: h, м | BH19: A, лет | BI19: Кол-во | BJ19: D, см | BK19: h, м | BL19: A, лет
B20: =AC20*AA20 | C20: =AI20*AG20 | D20: =W20*U20 | E20: =AK20*AM20 | F20: =AO20*AQ20 | G20: =AS20*AU20 | H20: =AW20*AY20 | I20: =BA20*BC20 | J20: =BE20*BG20 | K20: =BI20*BK20 | L20: =SUM(S20:U20,Y20:AA20,AE20:AG20,AK20,AO20,AS20,AW20,BA20,BE20,BI20)/($AE$16*$AE$16*3.15/10000*1000) | N20: 1 | O20: 965 | P20: КС/B2 | S20: 1e-06 | T20: 1e-06 | U20: 1e-06 | Y20: 1e-06 | Z20: 1e-06 | AA20: 1e-06 | AE20: 1e-06 | AF20: 1e-06 | AG20: 1e-06 | AK20: 1e-06 | AO20: 4 | AP20: 12 | AQ20: 16 | AR20: 25 | AS20: 1e-06 | AW20: 1e-06 | BA20: 1e-06 | BE20: 1e-06 | BI20: 5 | BJ20: 7 | BK20: 12 | BL20: 24
B21: =AC21*AA21 | C21: =AI21*AG21 | D21: =W21*U21 | E21: =AK21*AM21 | F21: =AO21*AQ21 | G21: =AS21*AU21 | H21: =AW21*AY21 | I21: =BA21*BC21 | J21: =BE21*BG21 | K21: =BI21*BK21 | L21: =SUM(S21:U21,Y21:AA21,AE21:AG21,AK21,AO21,AS21,AW21,BA21,BE21,BI21)/($AE$16*$AE$16*3.15/10000*1000) | N21: 2 | O21: 966 | P21: КС/B2 | AE21: 0 | AF21: 1 | AG21: 4 | AI21: 5.5 | AJ21: 23 | AK21: 7 | AL21: 9 | AM21: 14 | AN21: 24 | AO21: 1 | AP21: 4 | AQ21: 7 | AR21: 15 | AS21: 0 | BI21: 0
B22: =AC22*AA22 | C22: =AI22*AG22 | D22: =W22*U22 | E22: =AK22*AM22 | F22: =AO22*AQ22 | G22: =AS22*AU22 | H22: =AW22*AY22 | I22: =BA22*BC22 | J22: =BE22*BG22 | K22: =BI22*BK22 | L22: =SUM(S22:U22,Y22:AA22,AE22:AG22,AK22,AO22,AS22,AW22,BA22,BE22,BI22)/($AE$16*$AE$16*3.15/10000*1000) | N22: 3 | O22: 967 | P22: КС/B2 | AE22: 0 | AF22: 6 | AG22: 9 | AI22: 6.5 | AJ22: 26 | AK22: 2 | AL22: 4 | AM22: 3 | AN22: 20 | AO22: 0 | AS22: 0 | BI22: 0
B23: =AC23*AA23 | C23: =AI23*AG23 | D23: =W23*U23 | E23: =AK23*AM23 | F23: =AO23*AQ23 | G23: =AS23*AU23 | H23: =AW23*AY23 | I23: =BA23*BC23 | J23: =BE23*BG23 | K23: =BI23*BK23 | L23: =SUM(S23:U23,Y23:AA23,AE23:AG23,AK23,AO23,AS23,AW23,BA23,BE23,BI23)/($AE$16*$AE$16*3.15/10000*1000) | N23: 4 | O23: 968 | P23: КС/B2 | AE23: 0 | AF23: 0 | AG23: 0 | AK23: 0 | AO23: 4 | AP23: 9 | AQ23: 12 | AR23: 25 | AS23: 0 | BI23: 2 | BJ23: 9 | BK23: 12 | BL23: 25
B24: =AC24*AA24 | C24: =AI24*AG24 | D24: =W24*U24 | E24: =AK24*AM24 | F24: =AO24*AQ24 | G24: =AS24*AU24 | H24: =AW24*AY24 | I24: =BA24*BC24 | J24: =BE24*BG24 | K24: =BI24*BK24 | L24: =SUM(S24:U24,Y24:AA24,AE24:AG24,AK24,AO24,AS24,AW24,BA24,BE24,BI24)/($AE$16*$AE$16*3.15/10000*1000) | N24: 5 | O24: 969 | P24: КС/B2 | AE24: 0 | AF24: 0 | AG24: 0 | AK24: 0 | AO24: 0 | AS24: 0 | BI24: 9 | BJ24: 9 | BK24: 11 | BL24: 25
B25: =AC25*AA25 | C25: =AI25*AG25 | D25: =W25*U25 | E25: =AK25*AM25 | F25: =AO25*AQ25 | G25: =AS25*AU25 | H25: =AW25*AY25 | I25: =BA25*BC25 | J25: =BE25*BG25 | K25: =BI25*BK25 | L25: =SUM(S25:U25,Y25:AA25,AE25:AG25,AK25,AO25,AS25,AW25,BA25,BE25,BI25)/($AE$16*$AE$16*3.15/10000*1000) | N25: 6 | O25: 970 | P25: КС/B2 | AE25: 0 | AF25: 0 | AG25: 0 | AK25: 3 | AL25: 13 | AM25: 15 | AN25: 25 | AO25: 0 | AS25: 0 | BI25: 0
B26: =AC26*AA26 | C26: =AI26*AG26 | D26: =W26*U26 | E26: =AK26*AM26 | F26: =AO26*AQ26 | G26: =AS26*AU26 | H26: =AW26*AY26 | I26: =BA26*BC26 | J26: =BE26*BG26 | K26: =BI26*BK26 | L26: =SUM(S26:U26,Y26:AA26,AE26:AG26,AK26,AO26,AS26,AW26,BA26,BE26,BI26)/($AE$16*$AE$16*3.15/10000*1000) | N26: 7 | O26: 971 | P26: КС/B2 | AE26: 0 | AF26: 0 | AG26: 0 | AK26: 0 | AO26: 2 | AP26: 12 | AQ26: 14 | AR26: 25 | AS26: 0 | BI26: 10 | BJ26: 7 | BK26: 13 | BL26: 23
B27: =AC27*AA27 | C27: =AI27*AG27 | D27: =W27*U27 | E27: =AK27*AM27 | F27: =AO27*AQ27 | G27: =AS27*AU27 | H27: =AW27*AY27 | I27: =BA27*BC27 | J27: =BE27*BG27 | K27: =BI27*BK27 | L27: =SUM(S27:U27,Y27:AA27,AE27:AG27,AK27,AO27,AS27,AW27,BA27,BE27,BI27)/($AE$16*$AE$16*3.15/10000*1000) | N27: 8 | O27: 972 | P27: КС/B2 | AE27: 0 | AF27: 0 | AG27: 6 | AI27: 5.7 | AJ27: 25 | AK27: 5 | AL27: 11 | AM27: 15 | AN27: 25 | AO27: 1 | AP27: 8 | AQ27: 13 | AR27: 25 | AS27: 0 | BI27: 7 | BJ27: 5 | BK27: 5.5 | BL27: 19
B28: =AC28*AA28 | C28: =AI28*AG28 | D28: =W28*U28 | E28: =AK28*AM28 | F28: =AO28*AQ28 | G28: =AS28*AU28 | H28: =AW28*AY28 | I28: =BA28*BC28 | J28: =BE28*BG28 | K28: =BI28*BK28 | L28: =SUM(S28:U28,Y28:AA28,AE28:AG28,AK28,AO28,AS28,AW28,BA28,BE28,BI28)/($AE$16*$AE$16*3.15/10000*1000) | N28: 9 | O28: 973 | P28: КС/B2 | AE28: 0 | AF28: 0 | AG28: 0 | AK28: 0 | AO28: 3 | AP28: 12 | AQ28: 14 | AR28: 25 | AS28: 1 | AT28: 13 | AU28: 16 | AV28: 25 | BI28: 0
B29: =AC29*AA29 | C29: =AI29*AG29 | D29: =W29*U29 | E29: =AK29*AM29 | F29: =AO29*AQ29 | G29: =AS29*AU29 | H29: =AW29*AY29 | I29: =BA29*BC29 | J29: =BE29*BG29 | K29: =BI29*BK29 | L29: =SUM(S29:U29,Y29:AA29,AE29:AG29,AK29,AO29,AS29,AW29,BA29,BE29,BI29)/($AE$16*$AE$16*3.15/10000*1000) | N29: 10 | O29: 974 | P29: КС/B2 | AE29: 0 | AF29: 8 | AG29: 3 | AI29: 1.9 | AJ29: 20 | AK29: 0 | AO29: 1 | AP29: 11 | AQ29: 15 | AR29: 25 | AS29: 9 | AT29: 11 | AU29: 15 | AV29: 25 | BI29: 0
B30: =AC30*AA30 | C30: =AI30*AG30 | D30: =W30*U30 | E30: =AK30*AM30 | F30: =AO30*AQ30 | G30: =AS30*AU30 | H30: =AW30*AY30 | I30: =BA30*BC30 | J30: =BE30*BG30 | K30: =BI30*BK30 | L30: =SUM(S30:U30,Y30:AA30,AE30:AG30,AK30,AO30,AS30,AW30,BA30,BE30,BI30)/($AE$16*$AE$16*3.15/10000*1000) | N30: 11 | O30: 975 | P30: КС/B2 | AE30: 0 | AF30: 2 | AG30: 1 | AI30: 2.7 | AJ30: 20 | AK30: 0 | AO30: 5 | AP30: 12 | AQ30: 16 | AR30: 25 | AS30: 0 | BI30: 9 | BJ30: 7 | BK30: 9 | BL30: 20
B31: =AC31*AA31 | C31: =AI31*AG31 | D31: =W31*U31 | E31: =AK31*AM31 | F31: =AO31*AQ31 | G31: =AS31*AU31 | H31: =AW31*AY31 | I31: =BA31*BC31 | J31: =BE31*BG31 | K31: =BI31*BK31 | L31: =SUM(S31:U31,Y31:AA31,AE31:AG31,AK31,AO31,AS31,AW31,BA31,BE31,BI31)/($AE$16*$AE$16*3.15/10000*1000) | N31: 12
B32: =AC32*AA32 | C32: =AI32*AG32 | D32: =W32*U32 | E32: =AK32*AM32 | F32: =AO32*AQ32 | G32: =AS32*AU32 | H32: =AW32*AY32 | I32: =BA32*BC32 | J32: =BE32*BG32 | K32: =BI32*BK32 | L32: =SUM(S32:U32,Y32:AA32,AE32:AG32,AK32,AO32,AS32,AW32,BA32,BE32,BI32)/($AE$16*$AE$16*3.15/10000*1000) | N32: 13
B33: =AC33*AA33 | C33: =AI33*AG33 | D33: =W33*U33 | E33: =AK33*AM33 | F33: =AO33*AQ33 | G33: =AS33*AU33 | H33: =AW33*AY33 | I33: =BA33*BC33 | J33: =BE33*BG33 | K33: =BI33*BK33 | L33: =SUM(S33:U33,Y33:AA33,AE33:AG33,AK33,AO33,AS33,AW33,BA33,BE33,BI33)/($AE$16*$AE$16*3.15/10000*1000) | N33: 14
B34: =AC34*AA34 | C34: =AI34*AG34 | D34: =W34*U34 | E34: =AK34*AM34 | F34: =AO34*AQ34 | G34: =AS34*AU34 | H34: =AW34*AY34 | I34: =BA34*BC34 | J34: =BE34*BG34 | K34: =BI34*BK34 | L34: =SUM(S34:U34,Y34:AA34,AE34:AG34,AK34,AO34,AS34,AW34,BA34,BE34,BI34)/($AE$16*$AE$16*3.15/10000*1000) | N34: 15
B35: =AC35*AA35 | C35: =AI35*AG35 | D35: =W35*U35 | E35: =AK35*AM35 | F35: =AO35*AQ35 | G35: =AS35*AU35 | H35: =AW35*AY35 | I35: =BA35*BC35 | J35: =BE35*BG35 | K35: =BI35*BK35 | L35: =SUM(S35:U35,Y35:AA35,AE35:AG35,AK35,AO35,AS35,AW35,BA35,BE35,BI35)/($AE$16*$AE$16*3.15/10000*1000) | N35: 16
B36: =AC36*AA36 | C36: =AI36*AG36 | D36: =W36*U36 | E36: =AK36*AM36 | F36: =AO36*AQ36 | G36: =AS36*AU36 | H36: =AW36*AY36 | I36: =BA36*BC36 | J36: =BE36*BG36 | K36: =BI36*BK36 | L36: =SUM(S36:U36,Y36:AA36,AE36:AG36,AK36,AO36,AS36,AW36,BA36,BE36,BI36)/($AE$16*$AE$16*3.15/10000*1000) | N36: 17
B37: =AC37*AA37 | C37: =AI37*AG37 | D37: =W37*U37 | E37: =AK37*AM37 | F37: =AO37*AQ37 | G37: =AS37*AU37 | H37: =AW37*AY37 | I37: =BA37*BC37 | J37: =BE37*BG37 | K37: =BI37*BK37 | L37: =SUM(S37:U37,Y37:AA37,AE37:AG37,AK37,AO37,AS37,AW37,BA37,BE37,BI37)/($AE$16*$AE$16*3.15/10000*1000) | N37: 18
B38: =AC38*AA38 | C38: =AI38*AG38 | D38: =W38*U38 | E38: =AK38*AM38 | F38: =AO38*AQ38 | G38: =AS38*AU38 | H38: =AW38*AY38 | I38: =BA38*BC38 | J38: =BE38*BG38 | K38: =BI38*BK38 | L38: =SUM(S38:U38,Y38:AA38,AE38:AG38,AK38,AO38,AS38,AW38,BA38,BE38,BI38)/($AE$16*$AE$16*3.15/10000*1000) | N38: 19
B39: =AC39*AA39 | C39: =AI39*AG39 | D39: =W39*U39 | E39: =AK39*AM39 | F39: =AO39*AQ39 | G39: =AS39*AU39 | H39: =AW39*AY39 | I39: =BA39*BC39 | J39: =BE39*BG39 | K39: =BI39*BK39 | L39: =SUM(S39:U39,Y39:AA39,AE39:AG39,AK39,AO39,AS39,AW39,BA39,BE39,BI39)/($AE$16*$AE$16*3.15/10000*1000) | N39: 20
B40: =AC40*AA40 | C40: =AI40*AG40 | D40: =W40*U40 | E40: =AK40*AM40 | F40: =AO40*AQ40 | G40: =AS40*AU40 | H40: =AW40*AY40 | I40: =BA40*BC40 | J40: =BE40*BG40 | K40: =BI40*BK40 | L40: =SUM(S40:U40,Y40:AA40,AE40:AG40,AK40,AO40,AS40,AW40,BA40,BE40,BI40)/($AE$16*$AE$16*3.15/10000*1000) | N40: 21
B41: =AC41*AA41 | C41: =AI41*AG41 | D41: =W41*U41 | E41: =AK41*AM41 | F41: =AO41*AQ41 | G41: =AS41*AU41 | H41: =AW41*AY41 | I41: =BA41*BC41 | J41: =BE41*BG41 | K41: =BI41*BK41 | L41: =SUM(S41:U41,Y41:AA41,AE41:AG41,AK41,AO41,AS41,AW41,BA41,BE41,BI41)/($AE$16*$AE$16*3.15/10000*1000) | N41: 22
B42: =AC42*AA42 | C42: =AI42*AG42 | D42: =W42*U42 | E42: =AK42*AM42 | F42: =AO42*AQ42 | G42: =AS42*AU42 | H42: =AW42*AY42 | I42: =BA42*BC42 | J42: =BE42*BG42 | K42: =BI42*BK42 | L42: =SUM(S42:U42,Y42:AA42,AE42:AG42,AK42,AO42,AS42,AW42,BA42,BE42,BI42)/($AE$16*$AE$16*3.15/10000*1000) | N42: 23
... B51: =AC51*AA51 | C51: =AI51*AG51 | D51: =W51*U51 | E51: =AK51*AM51 | F51: =AO51*AQ51 | G51: =AS51*AU51 | H51: =AW51*AY51 | I51: =BA51*BC51 | J51: =BE51*BG51 | K51: =BI51*BK51 | L51: =SUM(S51:U51,Y51:AA51,AE51:AG51,AK51,AO51,AS51,AW51,BA51,BE51,BI51)/($AE$16*$AE$16*3.15/10000*1000) | N51: 32
N52: Среднее | S52: =AVERAGE(S20:S51) | T52: =AVERAGE(T20:T51) | U52: =AVERAGE(U20:U51) | V52: =AVERAGE(V20:V51) | W52: =(SUM(D20:D51)+SUM(T20:T51)+SUM(S20:S51)*0.35)/SUM(S20:U51) | X52: =AVERAGE(X20:X51) | Y52: =AVERAGE(Y20:Y51) | Z52: =AVERAGE(Z20:Z51) | AA52: =AVERAGE(AA20:AA51) | AB52: =AVERAGE(AB20:AB51) | AC52: =(SUM(B20:B51)+SUM(Z20:Z51)+SUM(Y20:Y51)*0.35)/SUM(Y20:AA51) | AD52: =AVERAGE(AD20:AD51) | AE52: =AVERAGE(AE20:AE51) | AF52: =AVERAGE(AF20:AF51) | AG52: =AVERAGE(AG20:AG51) | AH52: =AVERAGE(AH20:AH51) | AI52: =(SUM(C20:C51)+SUM(AF20:AF51)+SUM(AE20:AE51)*0.35)/SUM(AE20:AG51) | AJ52: =AVERAGE(AJ20:AJ51) | AK52: =AVERAGE(AK20:AK51) | AL52: =AVERAGE(AL20:AL51) | AM52: =SUM(E20:E51)/SUM(AK20:AK51) | AN52: =AVERAGE(AN20:AN51) | AO52: =AVERAGE(AO20:AO51) | AP52: =AVERAGE(AP20:AP51) | AQ52: =SUM(F20:F51)/SUM(AO20:AO51) | AR52: =AVERAGE(AR20:AR51) | AS52: =AVERAGE(AS20:AS51) | AT52: =AVERAGE(AT20:AT51) | AU52: =SUM(G20:G51)/SUM(AS20:AS51) | AV52: =AVERAGE(AV20:AV51) | AW52: =AVERAGE(AW20:AW51) | AX52: =AVERAGE(AX20:AX51) | AY52: =SUM(H20:H51)/SUM(AW20:AW51) | AZ52: =AVERAGE(AZ20:AZ51) | BA52: =AVERAGE(BA20:BA51) | BB52: =AVERAGE(BB20:BB51) | BC52: =SUM(I20:I51)/SUM(BA20:BA51) | BD52: =AVERAGE(BD20:BD51) | BE52: =AVERAGE(BE20:BE51) | BF52: =AVERAGE(BF20:BF51) | BG52: =SUM(J20:J51)/SUM(BE20:BE51) | BH52: =AVERAGE(BH20:BH51) | BI52: =AVERAGE(BI20:BI51) | BJ52: =AVERAGE(BJ20:BJ51) | BK52: =SUM(K20:K51)/SUM(BI20:BI51) | BL52: =AVERAGE(BL20:BL51)
N53: H выше 1.5 | W53: =SUM(D20:D51)/SUM(U20:U51) | AC53: =SUM(B20:B51)/SUM(AA20:AA51) | AI53: =SUM(C20:C51)/SUM(AG20:AG51)
N54: D
N55: A
...

Sheet Стр. 2 Породы (2)
B16: Перечётная ведомость № _1___ литер _б__ Кв. __113___ Выд. _16___ Радиус ПП, м __3.99____ Измерения выполнил: __Богачёв П.В._______ Дата, подпись _____11.06.2023______________
B18: Пор. | C18: Площадка | E18: Осина | I18: Ольха серая | M18: Ива | Q18: Чёрёмуха, Рябина | U18: =#REF!
B19: NN | C19: GPS точка | D19: ТЛ/ТУМ | E19: Кол-во | F19: D, см | G19: h, м | H19: A, лет | I19: Кол-во | J19: D, см | K19: h, м | L19: A, лет | M19: Кол-во | N19: D, см | O19: h, м | P19: A, лет | Q19: Кол-во | R19: D, см | S19: h, м | T19: A, лет | U19: Кол-во | V19: D, см | W19: h, м | X19: A, лет
B20: 1 | C20: 692 | D20: ЧС/В2 | E20: =#REF! | F20: =#REF! | G20: =#REF! | H20: =#REF! | I20: =#REF! | J20: =#REF! | K20: =#REF! | L20: =#REF! | ... P20: =#REF! | Q20: =#REF!+#REF! | R20: =((IF(#REF!=0,#REF!,#REF!))+(IF(#REF!=0,#REF!,#REF!)))/2 | S20: =((IF(#REF!=0,#REF!,#REF!))+(IF(#REF!=0,#REF!,#REF!)))/2 | T20: =((IF(#REF!=0,#REF!,#REF!))+(IF(#REF!=0,#REF!,#REF!)))/2 | U20: =#REF! | V20: =#REF! | W20: =#REF! | X20: =#REF!
B21: 2 | C21: 693 | D21: ЧС/В2 | E21: =#REF! | F21: =#REF! | G21: =#REF! | H21: =#REF! | I21: =#REF! | J21: =#REF! | K21: =#REF! | L21: =#REF! | ... P21: =#REF! | Q21: =#REF!+#REF! | R21: =((IF(#REF!=0,#REF!,#REF!))+(IF(#REF!=0,#REF!,#REF!)))/2 | S21: =((IF(#REF!=0,#REF!,#REF!))+(IF(#REF!=0,#REF!,#REF!)))/2 | T21: =((IF(#REF!=0,#REF!,#REF!))+(IF(#REF!=0,#REF!,#REF!)))/2 | U21: =#REF! | V21: =#REF! | W21: =#REF! | X21: =#REF!
B22: 3 | C22: 694 | D22: ЧС/В2 | E22: =#REF! | F22: =#REF! | G22: =#REF! | H22: =#REF! | I22: =#REF! | J22: =#REF! | K22: =#REF! | L22: =#REF! | ... P22: =#REF! | Q22: =#REF!+#REF! | R22: =((IF(#REF!=0,#REF!,#REF!))+(IF(#REF!=0,#REF!,#REF!)))/2 | S22: =((IF(#REF!=0,#REF!,#REF!))+(IF(#REF!=0,#REF!,#REF!)))/2 | T22: =((IF(#REF!=0,#REF!,#REF!))+(IF(#REF!=0,#REF!,#REF!)))/2 | U22: =#REF! | V22: =#REF! | W22: =#REF! | X22: =#REF!
B23: 4 | C23: 695 | D23: ЧС/В2 | E23: =#REF! | F23: =#REF! | G23: =#REF! | H23: =#REF! | I23: =#REF! | J23: =#REF! | K23: =#REF! | L23: =#REF! | ... P23: =#REF! | Q23: =#REF!+#REF! | R23: =((IF(#REF!=0,#REF!,#REF!))+(IF(#REF!=0,#REF!,#REF!)))/2 | S23: =((IF(#REF!=0,#REF!,#REF!))+(IF(#REF!=0,#REF!,#REF!)))/2 | T23: =((IF(#REF!=0,#REF!,#REF!))+(IF(#REF!=0,#REF!,#REF!)))/2 | U23: =#REF! | V23: =#REF! | W23: =#REF! | X23: =#REF!
B24: 5 | C24: 696 | D24: ДМ/В4 | E24: =#REF! | F24: =#REF! | G24: =#REF! | H24: =#REF! | I24: =#REF! | J24: =#REF! | K24: =#REF! | L24: =#REF! | ... P24: =#REF! | Q24: =#REF!+#REF! | R24: =((IF(#REF!=0,#REF!,#REF!))+(IF(#REF!=0,#REF!,#REF!)))/2 | S24: =((IF(#REF!=0,#REF!,#REF!))+(IF(#REF!=0,#REF!,#REF!)))/2 | T24: =((IF(#REF!=0,#REF!,#REF!))+(IF(#REF!=0,#REF!,#REF!)))/2 | U24: =#REF! | V24: =#REF! | W24: =#REF! | X24: =#REF!
B25: 6 | C25: 697 | D25: ЧС/В2 | E25: =#REF! | F25: =#REF! | G25: =#REF! | H25: =#REF! | I25: =#REF! | J25: =#REF! | K25: =#REF! | L25: =#REF! | ... P25: =#REF! | Q25: =#REF!+#REF! | R25: =((IF(#REF!=0,#REF!,#REF!))+(IF(#REF!=0,#REF!,#REF!)))/2 | S25: =((IF(#REF!=0,#REF!,#REF!))+(IF(#REF!=0,#REF!,#REF!)))/2 | T25: =((IF(#REF!=0,#REF!,#REF!))+(IF(#REF!=0,#REF!,#REF!)))/2 | U25: =#REF! | V25: =#REF! | W25: =#REF! | X25: =#REF!
B26: 7 | C26: 698 | D26: ЧС/В2 | E26: =#REF! | F26: =#REF! | G26: =#REF! | H26: =#REF! | I26: =#REF! | J26: =#REF! | K26: =#REF! | L26: =#REF! | ... P26: =#REF! | Q26: =#REF!+#REF! | R26: =((IF(#REF!=0,#REF!,#REF!))+(IF(#REF!=0,#REF!,#REF!)))/2 | S26: =((IF(#REF!=0,#REF!,#REF!))+(IF(#REF!=0,#REF!,#REF!)))/2 | T26: =((IF(#REF!=0,#REF!,#REF!))+(IF(#REF!=0,#REF!,#REF!)))/2 | U26: =#REF! | V26: =#REF! | W26: =#REF! | X26: =#REF!
B27: 8 | C27: 699 | D27: ЧС/В2 | E27: =#REF! | F27: =#REF! | G27: =#REF! | H27: =#REF! | I27: =#REF! | J27: =#REF! | K27: =#REF! | L27: =#REF! | ... P27: =#REF! | Q27: =#REF!+#REF! | R27: =((IF(#REF!=0,#REF!,#REF!))+(IF(#REF!=0,#REF!,#REF!)))/2 | S27: =((IF(#REF!=0,#REF!,#REF!))+(IF(#REF!=0,#REF!,#REF!)))/2 | T27: =((IF(#REF!=0,#REF!,#REF!))+(IF(#REF!=0,#REF!,#REF!)))/2 | U27: =#REF! | V27: =#REF! | W27: =#REF! | X27: =#REF!
B28: 9 | C28: 700 | D28: ЧС/В2 | E28: =#REF! | F28: =#REF! | G28: =#REF! | H28: =#REF! | I28: =#REF! | J28: =#REF! | K28: =#REF! | L28: =#REF! | ... P28: =#REF! | Q28: =#REF!+#REF! | R28: =((IF(#REF!=0,#REF!,#REF!))+(IF(#REF!=0,#REF!,#REF!)))/2 | S28: =((IF(#REF!=0,#REF!,#REF!))+(IF(#REF!=0,#REF!,#REF!)))/2 | T28: =((IF(#REF!=0,#REF!,#REF!))+(IF(#REF!=0,#REF!,#REF!)))/2 | U28: =#REF! | V28: =#REF! | W28: =#REF! | X28: =#REF!
B29: 10 | C29: 701 | D29: ЧС/В2 | E29: =#REF! | F29: =#REF! | G29: =#REF! | H29: =#REF! | I29: =#REF! | J29: =#REF! | K29: =#REF! | L29: =#REF! | ... P29: =#REF! | Q29: =#REF!+#REF! | R29: =((IF(#REF!=0,#REF!,#REF!))+(IF(#REF!=0,#REF!,#REF!)))/2 | S29: =((IF(#REF!=0,#REF!,#REF!))+(IF(#REF!=0,#REF!,#REF!)))/2 | T29: =((IF(#REF!=0,#REF!,#REF!))+(IF(#REF!=0,#REF!,#REF!)))/2 | U29: =#REF! | V29: =#REF! | W29: =#REF! | X29: =#REF!
B30: 11 | C30: 702 | D30: ЧС/В2 | E30: =#REF! | F30: =#REF! | G30: =#REF! | H30: =#REF! | I30: =#REF! | J30: =#REF! | K30: =#REF! | L30: =#REF! | ... P30: =#REF! | Q30: =#REF!+#REF! | R30: =((IF(#REF!=0,#REF!,#REF!))+(IF(#REF!=0,#REF!,#REF!)))/2 | S30: =((IF(#REF!=0,#REF!,#REF!))+(IF(#REF!=0,#REF!,#REF!)))/2 | T30: =((IF(#REF!=0,#REF!,#REF!))+(IF(#REF!=0,#REF!,#REF!)))/2 | U30: =#REF! | V30: =#REF! | W30: =#REF! | X30: =#REF!
B31: 12 | C31: 703 | D31: ЧС/В2 | E31: =#REF! | F31: =#REF! | G31: =#REF! | H31: =#REF! | I31: =#REF! | J31: =#REF! | K31: =#REF! | L31: =#REF! | ... P31: =#REF! | Q31: =#REF!+#REF! | R31: =((IF(#REF!=0,#REF!,#REF!))+(IF(#REF!=0,#REF!,#REF!)))/2 | S31: =((IF(#REF!=0,#REF!,#REF!))+(IF(#REF!=0,#REF!,#REF!)))/2 | T31: =((IF(#REF!=0,#REF!,#REF!))+(IF(#REF!=0,#REF!,#REF!)))/2 | U31: =#REF! | V31: =#REF! | W31: =#REF! | X31: =#REF!
... B34: 15 | C34: 706 | D34: ЧС/В2 | E34: =#REF! | F34: =#REF! | G34: =#REF! | H34: =#REF! | I34: =#REF! | J34: =#REF! | K34: =#REF! | L34: =#REF! | ... P34: =#REF! | Q34: =#REF!+#REF! | R34: =((IF(#REF!=0,#REF!,#REF!))+(IF(#REF!=0,#REF!,#REF!)))/2 | S34: =((IF(#REF!=0,#REF!,#REF!))+(IF(#REF!=0,#REF!,#REF!)))/2 | T34: =((IF(#REF!=0,#REF!,#REF!))+(IF(#REF!=0,#REF!,#REF!)))/2 | U34: =#REF! | V34: =#REF! | W34: =#REF! | X34: =#REF!
B35: 16 | E35: =#REF! | F35: =#REF! | G35: =#REF! | H35: =#REF! | I35: =#REF! | J35: =#REF! | K35: =#REF! | L35: =#REF! | ... P35: =#REF! | Q35: =#REF!+#REF! | R35: =((IF(#REF!=0,#REF!,#REF!))+(IF(#REF!=0,#REF!,#REF!)))/2 | S35: =((IF(#REF!=0,#REF!,#REF!))+(IF(#REF!=0,#REF!,#REF!)))/2 | T35: =((IF(#REF!=0,#REF!,#REF!))+(IF(#REF!=0,#REF!,#REF!)))/2 | U35: =#REF! | V35: =#REF! | W35: =#REF! | X35: =#REF!
B36: 17 | E36: =#REF! | F36: =#REF! | G36: =#REF! | H36: =#REF! | I36: =#REF! | J36: =#REF! | K36: =#REF! | L36: =#REF! | ... P36: =#REF! | Q36: =#REF!+#REF! | R36: =((IF(#REF!=0,#REF!,#REF!))+(IF(#REF!=0,#REF!,#REF!)))/2 | S36: =((IF(#REF!=0,#REF!,#REF!))+(IF(#REF!=0,#REF!,#REF!)))/2 | T36: =((IF(#REF!=0,#REF!,#REF!))+(IF(#REF!=0,#REF!,#REF!)))/2 | U36: =#REF! | V36: =#REF! | W36: =#REF! | X36: =#REF!
B37: 18 | E37: =#REF! | F37: =#REF! | G37: =#REF! | H37: =#REF! | I37: =#REF! | J37: =#REF! | K37: =#REF! | L37: =#REF! | ... P37: =#REF! | Q37: =#REF!+#REF! | R37: =((IF(#REF!=0,#REF!,#REF!))+(IF(#REF!=0,#REF!,#REF!)))/2 | S37: =((IF(#REF!=0,#REF!,#REF!))+(IF(#REF!=0,#REF!,#REF!)))/2 | T37: =((IF(#REF!=0,#REF!,#REF!))+(IF(#REF!=0,#REF!,#REF!)))/2 | U37: =#REF! | V37: =#REF! | W37: =#REF! | X37: =#REF!
B38: 19 | E38: =#REF! | F38: =#REF! | G38: =#REF! | H38: =#REF! | I38: =#REF! | J38: =#REF! | K38: =#REF! | L38: =#REF! | ... P38: =#REF! | Q38: =#REF!+#REF! | R38: =((IF(#REF!=0,#REF!,#REF!))+(IF(#REF!=0,#REF!,#REF!)))/2 | S38: =((IF(#REF!=0,#REF!,#REF!))+(IF(#REF!=0,#REF!,#REF!)))/2 | T38: =((IF(#REF!=0,#REF!,#REF!))+(IF(#REF!=0,#REF!,#REF!)))/2 | U38: =#REF! | V38: =#REF! | W38: =#REF! | X38: =#REF!
B39: 20 | E39: =#REF! | F39: =#REF! | G39: =#REF! | H39: =#REF! | I39: =#REF! | J39: =#REF! | K39: =#REF! | L39: =#REF! | ... P39: =#REF! | Q39: =#REF!+#REF! | R39: =((IF(#REF!=0,#REF!,#REF!))+(IF(#REF!=0,#REF!,#REF!)))/2 | S39: =((IF(#REF!=0,#REF!,#REF!))+(IF(#REF!=0,#REF!,#REF!)))/2 | T39: =((IF(#REF!=0,#REF!,#REF!))+(IF(#REF!=0,#REF!,#REF!)))/2 | U39: =#REF! | V39: =#REF! | W39: =#REF! | X39: =#REF!
B40: 21 | E40: =#REF! | F40: =#REF! | G40: =#REF! | H40: =#REF! | I40: =#REF! | J40: =#REF! | K40: =#REF! | L40: =#REF! | ... P40: =#REF! | Q40: =#REF!+#REF! | R40: =((IF(#REF!=0,#REF!,#REF!))+(IF(#REF!=0,#REF!,#REF!)))/2 | S40: =((IF(#REF!=0,#REF!,#REF!))+(IF(#REF!=0,#REF!,#REF!)))/2 | T40: =((IF(#REF!=0,#REF!,#REF!))+(IF(#REF!=0,#REF!,#REF!)))/2 | U40: =#REF! | V40: =#REF! | W40: =#REF! | X40: =#REF!
B41: 22 | E41: =#REF! | F41: =#REF! | G41: =#REF! | H41: =#REF! | I41: =#REF! | J41: =#REF! | K41: =#REF! | L41: =#REF! | ... P41: =#REF! | Q41: =#REF!+#REF! | R41: =((IF(#REF!=0,#REF!,#REF!))+(IF(#REF!=0,#REF!,#REF!)))/2 | S41: =((IF(#REF!=0,#REF!,#REF!))+(IF(#REF!=0,#REF!,#REF!)))/2 | T41: =((IF(#REF!=0,#REF!,#REF!))+(IF(#REF!=0,#REF!,#REF!)))/2 | U41: =#REF! | V41: =#REF! | W41: =#REF! | X41: =#REF!
B42: 23 | E42: =#REF! | F42: =#REF! | G42: =#REF! | H42: =#REF! | I42: =#REF! | J42: =#REF! | K42: =#REF! | L42: =#REF! | ... P42: =#REF! | Q42: =#REF!+#REF! | R42: =((IF(#REF!=0,#REF!,#REF!))+(IF(#REF!=0,#REF!,#REF!)))/2 | S42: =((IF(#REF!=0,#REF!,#REF!))+(IF(#REF!=0,#REF!,#REF!)))/2 | T42: =((IF(#REF!=0,#REF!,#REF!))+(IF(#REF!=0,#REF!,#REF!)))/2 | U42: =#REF! | V42: =#REF! | W42: =#REF! | X42: =#REF!
B43: 24 | E43: =#REF! | F43: =#REF! | G43: =#REF! | H43: =#REF! | I43: =#REF! | J43: =#REF! | K43: =#REF! | L43: =#REF! | ... P43: =#REF! | Q43: =#REF!+#REF! | R43: =((IF(#REF!=0,#REF!,#REF!))+(IF(#REF!=0,#REF!,#REF!)))/2 | S43: =((IF(#REF!=0,#REF!,#REF!))+(IF(#REF!=0,#REF!,#REF!)))/2 | T43: =((IF(#REF!=0,#REF!,#REF!))+(IF(#REF!=0,#REF!,#REF!)))/2 | U43: =#REF! | V43: =#REF! | W43: =#REF! | X43: =#REF!
B44: 25 | E44: =#REF! | F44: =#REF! | G44: =#REF! | H44: =#REF! | I44: =#REF! | J44: =#REF! | K44: =#REF! | L44: =#REF! | ... P44: =#REF! | Q44: =#REF!+#REF! | R44: =((IF(#REF!=0,#REF!,#REF!))+(IF(#REF!=0,#REF!,#REF!)))/2 | S44: =((IF(#REF!=0,#REF!,#REF!))+(IF(#REF!=0,#REF!,#REF!)))/2 | T44: =((IF(#REF!=0,#REF!,#REF!))+(IF(#REF!=0,#REF!,#REF!)))/2 | U44: =#REF! | V44: =#REF! | W44: =#REF! | X44: =#REF!
B45: Среднее (тыс.шт/га; см; м; лет) | E45: =#REF! | F45: =#REF! | G45: =#REF! | H45: =#REF! | I45: =#REF! | J45: =#REF! | K45: =#REF! | L45: =#REF! | ... P45: =#REF! | Q45: =#REF!+#REF! | R45: =((IF(#REF!=0,#REF!,#REF!))+(IF(#REF!=0,#REF!,#REF!)))/2 | S45: =((IF(#REF!=0,#REF!,#REF!))+(IF(#REF!=0,#REF!,#REF!)))/2 | T45: =((IF(#REF!=0,#REF!,#REF!))+(IF(#REF!=0,#REF!,#REF!)))/2 | U45: =#REF! | V45: =#REF! | W45: =#REF! | X45: =#REF!
B46: H выше 1.5 (метров) | E46: =#REF! | F46: =#REF! | G46: =#REF! | H46: =#REF! | I46: =#REF! | J46: =#REF! | K46: =#REF! | L46: =#REF! | ... P46: =#REF! | Q46: =#REF!+#REF! | R46: =((IF(#REF!=0,#REF!,#REF!))+(IF(#REF!=0,#REF!,#REF!)))/2 | S46: =((IF(#REF!=0,#REF!,#REF!))+(IF(#REF!=0,#REF!,#REF!)))/2 | T46: =((IF(#REF!=0,#REF!,#REF!))+(IF(#REF!=0,#REF!,#REF!)))/2 | U46: =#REF! | V46: =#REF! | W46: =#REF! | X46: =#REF!

Sheet До рубки 205 д.2
W2: ИНСТРУКЦИЯ | AE2: 8 | AF2: Скопировать итоговые характеристики насаждения "До" и "После" в лист "Расчёты для проекта"
V3: 1 | W3: Скопировать лист внутри книги Excel | AE3: 9 | AF3: Заполнить Проект рубок ухода
V4: 2 | W4: Указать стадию (переименовать лист) "До рубки" | AE4: 10 | AF4: Скопировать данные перечёта по породам в Перечётные ведомости
V5: 3 | W5: Заполнит информацию о делянке (номер ведомости, квартал, выдел и т.д.) | AE5: 11 | AF5: Оформить пакет сопроводительной документация на делянку
V6: 4 | W6: Ввести данные перечёта | AE6: 12 | AF6: Подать уведомление в лесничество
V7: 5 | W7: Скопировать лист "до рубки" внутри книги Excel | AE7: 13 | AF7: Провести рубку
V8: 6 | W8: Указать стадию (переименовать лист) "После рубки" | AE8: 14
V9: 7 | W9: Удалить из ведомости перечёта то, что проектируется удалить в натуре | AE9: 15
N13: Стадия (до, проект или после рубки)
N16: Перечётная ведомость | S16: 1 | U16: Кв | V16: 205 | X16: Выд | Y16: 35 | Z16: делянка | AA16: 2 | AC16: Радиус ПП, м | AE16: 1.78 | AG16: Измерения выполнил: __________________ Дата, подпись, расшифровка _________________________
B18: Костыль для высоты | N18: Пор. | O18: Площадка | S18: Сосна | Y18: Ель из подроста | AE18: ЕЛЬ лесные культуры | AK18: Берёза | AO18: Осина | AS18: Ольха серая | AW18: Ива | BA18: Чёрёмуха | BE18: Дуб | BI18: Рябина
B19: =Y18 | C19: =AE18 | D19: =S18 | E19: =AK18 | F19: =AO18 | G19: =AS18 | H19: =AW18 | I19: =BA18 | J19: =BE18 | K19: =BI18 | L19: Всего, тыс.шт/га | N19: NN | O19: GPS точка | P19: ТЛ/ТУМ | Q19: Предмет ухода | R19: примечание | S19: До 0.5м | T19: 0,5-1,5 | U19: > 1.5 | V19: D, см | W19: h, м | X19: A, лет | Y19: До 0.5м | Z19: 0,5-1,5 | AA19: > 1.5 | AB19: D, см | AC19: h, м | AD19: A, лет | AE19: До 0.5м | AF19: 0,5-1,5 | AG19: > 1.5 | AH19: D, см | AI19: h, м | AJ19: A, лет | AK19: Кол-во | AL19: D, см | AM19: h, м | AN19: A, лет | AO19: Кол-во | AP19: D, см | AQ19: h, м | AR19: A, лет | AS19: Кол-во | AT19: D, см | AU19: h, м | AV19: A, лет | AW19: Кол-во | AX19: D, см | AY19: h, м | AZ19: A, лет | BA19: Кол-во | BB19: D, см | BC19: h, м | BD19: A, лет | BE19: Кол-во | BF19: D, см | BG19: h, м | BH19: A, лет | BI19: Кол-во | BJ19: D, см | BK19: h, м | BL19: A, лет
B20: =AC20*AA20 | C20: =AI20*AG20 | D20: =W20*U20 | E20: =AK20*AM20 | F20: =AO20*AQ20 | G20: =AS20*AU20 | H20: =AW20*AY20 | I20: =BA20*BC20 | J20: =BE20*BG20 | K20: =BI20*BK20 | L20: =SUM(S20:U20,Y20:AA20,AE20:AG20,AK20,AO20,AS20,AW20,BA20,BE20,BI20)/($AE$16*$AE$16*3.15/10000*1000) | N20: 1 | O20: 803 | S20: 1e-06 | T20: 1e-06 | U20: 1e-06 | Y20: 1e-06 | Z20: 1e-06 | AA20: 1 | AC20: 4 | AD20: 15 | AE20: 1e-06 | AF20: 1e-06 | AG20: 1e-06 | AK20: 5 | AM20: 2.5 | AN20: 10 | AO20: 1e-06 | AS20: 12 | AU20: 10 | AV20: 10 | AW20: 1e-06 | BA20: 1e-06 | BE20: 1e-06 | BI20: 1e-06
B21: =AC21*AA21 | C21: =AI21*AG21 | D21: =W21*U21 | E21: =AK21*AM21 | F21: =AO21*AQ21 | G21: =AS21*AU21 | H21: =AW21*AY21 | I21: =BA21*BC21 | J21: =BE21*BG21 | K21: =BI21*BK21 | L21: =SUM(S21:U21,Y21:AA21,AE21:AG21,AK21,AO21,AS21,AW21,BA21,BE21,BI21)/($AE$16*$AE$16*3.15/10000*1000) | N21: 2 | O21: 804 | S21: 0 | T21: 0 | U21: 0 | Y21: 0 | Z21: 0 | AA21: 0 | AE21: 0 | AF21: 0 | AG21: 0 | AK21: 1 | AM21: 18 | AN21: 25 | AO21: 0 | AS21: 4 | AU21: 18 | AV21: 25 | AW21: 0 | BA21: 0 | BE21: 0 | BI21: 0
B22: =AC22*AA22 | C22: =AI22*AG22 | D22: =W22*U22 | E22: =AK22*AM22 | F22: =AO22*AQ22 | G22: =AS22*AU22 | H22: =AW22*AY22 | I22: =BA22*BC22 | J22: =BE22*BG22 | K22: =BI22*BK22 | L22: =SUM(S22:U22,Y22:AA22,AE22:AG22,AK22,AO22,AS22,AW22,BA22,BE22,BI22)/($AE$16*$AE$16*3.15/10000*1000) | N22: 3 | O22: 805 | S22: 0 | T22: 0 | U22: 0 | Y22: 0 | Z22: 0 | AA22: 0 | AE22: 0 | AF22: 0 | AG22: 0 | AK22: 0 | AO22: 12 | AQ22: 8 | AR22: 15 | AS22: 4 | AU22: 5 | AV22: 15 | AW22: 0 | BA22: 0 | BE22: 0 | BI22: 0
B23: =AC23*AA23 | C23: =AI23*AG23 | D23: =W23*U23 | E23: =AK23*AM23 | F23: =AO23*AQ23 | G23: =AS23*AU23 | H23: =AW23*AY23 | I23: =BA23*BC23 | J23: =BE23*BG23 | K23: =BI23*BK23 | L23: =SUM(S23:U23,Y23:AA23,AE23:AG23,AK23,AO23,AS23,AW23,BA23,BE23,BI23)/($AE$16*$AE$16*3.15/10000*1000) | N23: 4 | O23: 806 | S23: 0 | T23: 0 | U23: 0 | Y23: 0 | Z23: 0 | AA23: 1 | AC23: 2.5 | AD23: 15 | AE23: 0 | AF23: 0 | AG23: 0 | AK23: 0 | AO23: 0 | AS23: 9 | AU23: 13 | AV23: 15 | AW23: 0 | BA23: 0 | BE23: 0 | BI23: 0
B24: =AC24*AA24 | C24: =AI24*AG24 | D24: =W24*U24 | E24: =AK24*AM24 | F24: =AO24*AQ24 | G24: =AS24*AU24 | H24: =AW24*AY24 | I24: =BA24*BC24 | J24: =BE24*BG24 | K24: =BI24*BK24 | L24: =SUM(S24:U24,Y24:AA24,AE24:AG24,AK24,AO24,AS24,AW24,BA24,BE24,BI24)/($AE$16*$AE$16*3.15/10000*1000) | N24: 5 | O24: 807 | S24: 0 | T24: 0 | U24: 0 | Y24: 0 | Z24: 0 | AA24: 2 | AC24: 1.5 | AD24: 10 | AE24: 0 | AF24: 0 | AG24: 0 | AK24: 4 | AM24: 17 | AN24: 20 | AO24: 0 | AS24: 10 | AU24: 5 | AV24: 10 | AW24: 0 | BA24: 0 | BE24: 0 | BI24: 0
B25: =AC25*AA25 | C25: =AI25*AG25 | D25: =W25*U25 | E25: =AK25*AM25 | F25: =AO25*AQ25 | G25: =AS25*AU25 | H25: =AW25*AY25 | I25: =BA25*BC25 | J25: =BE25*BG25 | K25: =BI25*BK25 | L25: =SUM(S25:U25,Y25:AA25,AE25:AG25,AK25,AO25,AS25,AW25,BA25,BE25,BI25)/($AE$16*$AE$16*3.15/10000*1000) | N25: 6 | O25: 808 | S25: 0 | T25: 0 | U25: 0 | Y25: 0 | Z25: 0 | AA25: 0 | AE25: 0 | AF25: 0 | AG25: 0 | AK25: 0 | AO25: 0 | AS25: 6 | AU25: 8 | AV25: 15 | AW25: 0 | BA25: 0 | BE25: 0 | BI25: 0
B26: =AC26*AA26 | C26: =AI26*AG26 | D26: =W26*U26 | E26: =AK26*AM26 | F26: =AO26*AQ26 | G26: =AS26*AU26 | H26: =AW26*AY26 | I26: =BA26*BC26 | J26: =BE26*BG26 | K26: =BI26*BK26 | L26: =SUM(S26:U26,Y26:AA26,AE26:AG26,AK26,AO26,AS26,AW26,BA26,BE26,BI26)/($AE$16*$AE$16*3.15/10000*1000) | N26: 7
B27: =AC27*AA27 | C27: =AI27*AG27 | D27: =W27*U27 | E27: =AK27*AM27 | F27: =AO27*AQ27 | G27: =AS27*AU27 | H27: =AW27*AY27 | I27: =BA27*BC27 | J27: =BE27*BG27 | K27: =BI27*BK27 | L27: =SUM(S27:U27,Y27:AA27,AE27:AG27,AK27,AO27,AS27,AW27,BA27,BE27,BI27)/($AE$16*$AE$16*3.15/10000*1000) | N27: 8
B28: =AC28*AA28 | C28: =AI28*AG28 | D28: =W28*U28 | E28: =AK28*AM28 | F28: =AO28*AQ28 | G28: =AS28*AU28 | H28: =AW28*AY28 | I28: =BA28*BC28 | J28: =BE28*BG28 | K28: =BI28*BK28 | L28: =SUM(S28:U28,Y28:AA28,AE28:AG28,AK28,AO28,AS28,AW28,BA28,BE28,BI28)/($AE$16*$AE$16*3.15/10000*1000) | N28: 9
B29: =AC29*AA29 | C29: =AI29*AG29 | D29: =W29*U29 | E29: =AK29*AM29 | F29: =AO29*AQ29 | G29: =AS29*AU29 | H29: =AW29*AY29 | I29: =BA29*BC29 | J29: =BE29*BG29 | K29: =BI29*BK29 | L29: =SUM(S29:U29,Y29:AA29,AE29:AG29,AK29,AO29,AS29,AW29,BA29,BE29,BI29)/($AE$16*$AE$16*3.15/10000*1000) | N29: 10
B30: =AC30*AA30 | C30: =AI30*AG30 | D30: =W30*U30 | E30: =AK30*AM30 | F30: =AO30*AQ30 | G30: =AS30*AU30 | H30: =AW30*AY30 | I30: =BA30*BC30 | J30: =BE30*BG30 | K30: =BI30*BK30 | L30: =SUM(S30:U30,Y30:AA30,AE30:AG30,AK30,AO30,AS30,AW30,BA30,BE30,BI30)/($AE$16*$AE$16*3.15/10000*1000) | N30: 11
B31: =AC31*AA31 | C31: =AI31*AG31 | D31: =W31*U31 | E31: =AK31*AM31 | F31: =AO31*AQ31 | G31: =AS31*AU31 | H31: =AW31*AY31 | I31: =BA31*BC31 | J31: =BE31*BG31 | K31: =BI31*BK31 | L31: =SUM(S31:U31,Y31:AA31,AE31:AG31,AK31,AO31,AS31,AW31,BA31,BE31,BI31)/($AE$16*$AE$16*3.15/10000*1000) | N31: 12
B32: =AC32*AA32 | C32: =AI32*AG32 | D32: =W32*U32 | E32: =AK32*AM32 | F32: =AO32*AQ32 | G32: =AS32*AU32 | H32: =AW32*AY32 | I32: =BA32*BC32 | J32: =BE32*BG32 | K32: =BI32*BK32 | L32: =SUM(S32:U32,Y32:AA32,AE32:AG32,AK32,AO32,AS32,AW32,BA32,BE32,BI32)/($AE$16*$AE$16*3.15/10000*1000) | N32: 13
B33: =AC33*AA33 | C33: =AI33*AG33 | D33: =W33*U33 | E33: =AK33*AM33 | F33: =AO33*AQ33 | G33: =AS33*AU33 | H33: =AW33*AY33 | I33: =BA33*BC33 | J33: =BE33*BG33 | K33: =BI33*BK33 | L33: =SUM(S33:U33,Y33:AA33,AE33:AG33,AK33,AO33,AS33,AW33,BA33,BE33,BI33)/($AE$16*$AE$16*3.15/10000*1000) | N33: 14
B34: =AC34*AA34 | C34: =AI34*AG34 | D34: =W34*U34 | E34: =AK34*AM34 | F34: =AO34*AQ34 | G34: =AS34*AU34 | H34: =AW34*AY34 | I34: =BA34*BC34 | J34: =BE34*BG34 | K34: =BI34*BK34 | L34: =SUM(S34:U34,Y34:AA34,AE34:AG34,AK34,AO34,AS34,AW34,BA34,BE34,BI34)/($AE$16*$AE$16*3.15/10000*1000) | N34: 15
B35: =AC35*AA35 | C35: =AI35*AG35 | D35: =W35*U35 | E35: =AK35*AM35 | F35: =AO35*AQ35 | G35: =AS35*AU35 | H35: =AW35*AY35 | I35: =BA35*BC35 | J35: =BE35*BG35 | K35: =BI35*BK35 | L35: =SUM(S35:U35,Y35:AA35,AE35:AG35,AK35,AO35,AS35,AW35,BA35,BE35,BI35)/($AE$16*$AE$16*3.15/10000*1000) | N35: 16
B36: =AC36*AA36 | C36: =AI36*AG36 | D36: =W36*U36 | E36: =AK36*AM36 | F36: =AO36*AQ36 | G36: =AS36*AU36 | H36: =AW36*AY36 | I36: =BA36*BC36 | J36: =BE36*BG36 | K36: =BI36*BK36 | L36: =SUM(S36:U36,Y36:AA36,AE36:AG36,AK36,AO36,AS36,AW36,BA36,BE36,BI36)/($AE$16*$AE$16*3.15/10000*1000) | N36: 17
B37: =AC37*AA37 | C37: =AI37*AG37 | D37: =W37*U37 | E37: =AK37*AM37 | F37: =AO37*AQ37 | G37: =AS37*AU37 | H37: =AW37*AY37 | I37: =BA37*BC37 | J37: =BE37*BG37 | K37: =BI37*BK37 | L37: =SUM(S37:U37,Y37:AA37,AE37:AG37,AK37,AO37,AS37,AW37,BA37,BE37,BI37)/($AE$16*$AE$16*3.15/10000*1000) | N37: 18
... B51: =AC51*AA51 | C51: =AI51*AG51 | D51: =W51*U51 | E51: =AK51*AM51 | F51: =AO51*AQ51 | G51: =AS51*AU51 | H51: =AW51*AY51 | I51: =BA51*BC51 | J51: =BE51*BG51 | K51: =BI51*BK51 | L51: =SUM(S51:U51,Y51:AA51,AE51:AG51,AK51,AO51,AS51,AW51,BA51,BE51,BI51)/($AE$16*$AE$16*3.15/10000*1000) | N51: 32
N52: Среднее | S52: =AVERAGE(S20:S51) | T52: =AVERAGE(T20:T51) | U52: =AVERAGE(U20:U51) | V52: =AVERAGE(V20:V51) | W52: =(SUM(D20:D51)+SUM(T20:T51)+SUM(S20:S51)*0.35)/SUM(S20:U51) | X52: =AVERAGE(X20:X51) | Y52: =AVERAGE(Y20:Y51) | Z52: =AVERAGE(Z20:Z51) | AA52: =AVERAGE(AA20:AA51) | AB52: =AVERAGE(AB20:AB51) | AC52: =(SUM(B20:B51)+SUM(Z20:Z51)+SUM(Y20:Y51)*0.35)/SUM(Y20:AA51) | AD52: =AVERAGE(AD20:AD51) | AE52: =AVERAGE(AE20:AE51) | AF52: =AVERAGE(AF20:AF51) | AG52: =AVERAGE(AG20:AG51) | AH52: =AVERAGE(AH20:AH51) | AI52: =(SUM(C20:C51)+SUM(AF20:AF51)+SUM(AE20:AE51)*0.35)/SUM(AE20:AG51) | AJ52: =AVERAGE(AJ20:AJ51) | AK52: =AVERAGE(AK20:AK51) | AL52: =AVERAGE(AL20:AL51) | AM52: =SUM(E20:E51)/SUM(AK20:AK51) | AN52: =AVERAGE(AN20:AN51) | AO52: =AVERAGE(AO20:AO51) | AP52: =AVERAGE(AP20:AP51) | AQ52: =SUM(F20:F51)/SUM(AO20:AO51) | AR52: =AVERAGE(AR20:AR51) | AS52: =AVERAGE(AS20:AS51) | AT52: =AVERAGE(AT20:AT51) | AU52: =SUM(G20:G51)/SUM(AS20:AS51) | AV52: =AVERAGE(AV20:AV51) | AW52: =AVERAGE(AW20:AW51) | AX52: =AVERAGE(AX20:AX51) | AY52: =SUM(H20:H51)/SUM(AW20:AW51) | AZ52: =AVERAGE(AZ20:AZ51) | BA52: =AVERAGE(BA20:BA51) | BB52: =AVERAGE(BB20:BB51) | BC52: =SUM(I20:I51)/SUM(BA20:BA51) | BD52: =AVERAGE(BD20:BD51) | BE52: =AVERAGE(BE20:BE51) | BF52: =AVERAGE(BF20:BF51) | BG52: =SUM(J20:J51)/SUM(BE20:BE51) | BH52: =AVERAGE(BH20:BH51) | BI52: =AVERAGE(BI20:BI51) | BJ52: =AVERAGE(BJ20:BJ51) | BK52: =SUM(K20:K51)/SUM(BI20:BI51) | BL52: =AVERAGE(BL20:BL51)
N53: H выше 1.5 | W53: =SUM(D20:D51)/SUM(U20:U51) | AC53: =SUM(B20:B51)/SUM(AA20:AA51) | AI53: =SUM(C20:C51)/SUM(AG20:AG51)
N54: D
N55: A
U60: =T13 | V60: Рубки
B61: Костыль для итоговых значений | O61: Итоговая характеристика насаждения
B62: =V62 | C62: =W62 | D62: =X62 | U62: Густота | V62: =AB19 | W62: =AC19 | X62: =AD19
B63: =V63*U63 | C63: =W63*U63 | D63: =X63*U63 | O63: =U63/$U$75*10 | R63: =S18 | U63: =SUM(S52:U52)/(AE16*AE16*3.15/10000*1000) | V63: =V52 | W63: =W52 | X63: =X52
B64: =V64*U64 | C64: =W64*U64 | D64: =X64*U64 | O64: =U64/$U$75*10 | R64: =Y18 | U64: =SUM(Y52:AA52)/(AE16*AE16*3.15/10000*1000) | V64: =AB52 | W64: =AC52 | X64: =AD52
...

Sheet До рубки 183 в 10(осв)
W2: ИНСТРУКЦИЯ | AE2: 8 | AF2: Скопировать итоговые характеристики насаждения "До" и "После" в лист "Расчёты для проекта"
V3: 1 | W3: Скопировать лист внутри книги Excel | AE3: 9 | AF3: Заполнить Проект рубок ухода
V4: 2 | W4: Указать стадию (переименовать лист) "До рубки" | AE4: 10 | AF4: Скопировать данные перечёта по породам в Перечётные ведомости
V5: 3 | W5: Заполнит информацию о делянке (номер ведомости, квартал, выдел и т.д.) | AE5: 11 | AF5: Оформить пакет сопроводительной документация на делянку
V6: 4 | W6: Ввести данные перечёта | AE6: 12 | AF6: Подать уведомление в лесничество
V7: 5 | W7: Скопировать лист "до рубки" внутри книги Excel | AE7: 13 | AF7: Провести рубку
V8: 6 | W8: Указать стадию (переименовать лист) "После рубки" | AE8: 14
V9: 7 | W9: Удалить из ведомости перечёта то, что проектируется удалить в натуре | AE9: 15
N13: Стадия (до, проект или после рубки)
N16: Перечётная ведомость | S16: 1 | U16: Кв | V16: 183 | X16: Выд | Y16: 10 | Z16: делянка | AA16: 1 | AC16: Радиус ПП, м | AE16: 1.78 | AG16: Измерения выполнил: __________________ Дата, подпись, расшифровка _________________________
B18: Костыль для высоты | N18: Пор. | O18: Площадка | S18: Сосна | Y18: Ель из подроста | AE18: ЕЛЬ лесные культуры | AK18: Берёза | AO18: Осина | AS18: Ольха серая | AW18: Ива | BA18: Чёрёмуха | BE18: Дуб | BI18: Рябина
B19: =Y18 | C19: =AE18 | D19: =S18 | E19: =AK18 | F19: =AO18 | G19: =AS18 | H19: =AW18 | I19: =BA18 | J19: =BE18 | K19: =BI18 | L19: Всего, тыс.шт/га | N19: NN | O19: GPS точка | P19: ТЛ/ТУМ | Q19: Предмет ухода | R19: примечание | S19: До 0.5м | T19: 0,5-1,5 | U19: > 1.5 | V19: D, см | W19: h, м | X19: A, лет | Y19: До 0.5м | Z19: 0,5-1,5 | AA19: > 1.5 | AB19: D, см | AC19: h, м | AD19: A, лет | AE19: До 0.5м | AF19: 0,5-1,5 | AG19: > 1.5 | AH19: D, см | AI19: h, м | AJ19: A, лет | AK19: Кол-во | AL19: D, см | AM19: h, м | AN19: A, лет | AO19: Кол-во | AP19: D, см | AQ19: h, м | AR19: A, лет | AS19: Кол-во | AT19: D, см | AU19: h, м | AV19: A, лет | AW19: Кол-во | AX19: D, см | AY19: h, м | AZ19: A, лет | BA19: Кол-во | BB19: D, см | BC19: h, м | BD19: A, лет | BE19: Кол-во | BF19: D, см | BG19: h, м | BH19: A, лет | BI19: Кол-во | BJ19: D, см | BK19: h, м | BL19: A, лет
B20: =AC20*AA20 | C20: =AI20*AG20 | D20: =W20*U20 | E20: =AK20*AM20 | F20: =AO20*AQ20 | G20: =AS20*AU20 | H20: =AW20*AY20 | I20: =BA20*BC20 | J20: =BE20*BG20 | K20: =BI20*BK20 | L20: =SUM(S20:U20,Y20:AA20,AE20:AG20,AK20,AO20,AS20,AW20,BA20,BE20,BI20)/($AE$16*$AE$16*3.15/10000*1000) | N20: 1 | O20: 890 | P20: БР/В2 | Q20: 3Е | S20: 1e-06 | T20: 1e-06 | U20: 1e-06 | Y20: 1e-06 | Z20: 1e-06 | AA20: 1e-06 | AE20: 3 | AF20: 1 | AG20: 5 | AI20: 2 | AJ20: 8 | AK20: 1e-06 | AL20: 0 | AM20: 0 | AO20: 1e-06 | AP20: 0 | AQ20: 0 | AS20: 1e-06 | AT20: 0 | AU20: 0 | AW20: 6 | AX20: 0 | AY20: 0.7 | AZ20: 4 | BA20: 1e-06 | BB20: 0 | BC20: 0 | BE20: 1e-06 | BF20: 0 | BG20: 0 | BI20: 1e-06 | BJ20: 0 | BK20: 0
B21: =AC21*AA21 | C21: =AI21*AG21 | D21: =W21*U21 | E21: =AK21*AM21 | F21: =AO21*AQ21 | G21: =AS21*AU21 | H21: =AW21*AY21 | I21: =BA21*BC21 | J21: =BE21*BG21 | K21: =BI21*BK21 | L21: =SUM(S21:U21,Y21:AA21,AE21:AG21,AK21,AO21,AS21,AW21,BA21,BE21,BI21)/($AE$16*$AE$16*3.15/10000*1000) | N21: 2 | O21: 891 | P21: ЧС/A2 | Q21: 3Б | AE21: 0 | AF21: 4 | AG21: 0 | AJ21: 8 | AK21: 17 | AM21: 2.5 | AN21: 8 | AS21: 16 | AU21: 2.1 | AV21: 8
B22: =AC22*AA22 | C22: =AI22*AG22 | D22: =W22*U22 | E22: =AK22*AM22 | F22: =AO22*AQ22 | G22: =AS22*AU22 | H22: =AW22*AY22 | I22: =BA22*BC22 | J22: =BE22*BG22 | K22: =BI22*BK22 | L22: =SUM(S22:U22,Y22:AA22,AE22:AG22,AK22,AO22,AS22,AW22,BA22,BE22,BI22)/($AE$16*$AE$16*3.15/10000*1000) | N22: 3 | O22: 892 | P22: ЧС/A2 | Q22: 1Б2Ос | AE22: 0 | AF22: 0 | AG22: 0 | AK22: 1 | AM22: 1.7 | AN22: 8 | AO22: 15 | AP22: 5 | AQ22: 4 | AR22: 10 | AS22: 19 | AU22: 2.3 | AV22: 10
B23: =AC23*AA23 | C23: =AI23*AG23 | D23: =W23*U23 | E23: =AK23*AM23 | F23: =AO23*AQ23 | G23: =AS23*AU23 | H23: =AW23*AY23 | I23: =BA23*BC23 | J23: =BE23*BG23 | K23: =BI23*BK23 | L23: =SUM(S23:U23,Y23:AA23,AE23:AG23,AK23,AO23,AS23,AW23,BA23,BE23,BI23)/($AE$16*$AE$16*3.15/10000*1000) | N23: 4 | O23: 893 | P23: ЧС/A2 | Q23: 2Б1Е | AE23: 3 | AF23: 4 | AG23: 0 | AJ23: 10 | AK23: 9 | AM23: 2.5 | AN23: 10 | AS23: 19 | AU23: 2.5 | AV23: 10
B24: =AC24*AA24 | C24: =AI24*AG24 | D24: =W24*U24 | E24: =AK24*AM24 | F24: =AO24*AQ24 | G24: =AS24*AU24 | H24: =AW24*AY24 | I24: =BA24*BC24 | J24: =BE24*BG24 | K24: =BI24*BK24 | L24: =SUM(S24:U24,Y24:AA24,AE24:AG24,AK24,AO24,AS24,AW24,BA24,BE24,BI24)/($AE$16*$AE$16*3.15/10000*1000) | N24: 5
B25: =AC25*AA25 | C25: =AI25*AG25 | D25: =W25*U25 | E25: =AK25*AM25 | F25: =AO25*AQ25 | G25: =AS25*AU25 | H25: =AW25*AY25 | I25: =BA25*BC25 | J25: =BE25*BG25 | K25: =BI25*BK25 | L25: =SUM(S25:U25,Y25:AA25,AE25:AG25,AK25,AO25,AS25,AW25,BA25,BE25,BI25)/($AE$16*$AE$16*3.15/10000*1000) | N25: 6
B26: =AC26*AA26 | C26: =AI26*AG26 | D26: =W26*U26 | E26: =AK26*AM26 | F26: =AO26*AQ26 | G26: =AS26*AU26 | H26: =AW26*AY26 | I26: =BA26*BC26 | J26: =BE26*BG26 | K26: =BI26*BK26 | L26: =SUM(S26:U26,Y26:AA26,AE26:AG26,AK26,AO26,AS26,AW26,BA26,BE26,BI26)/($AE$16*$AE$16*3.15/10000*1000) | N26: 7
B27: =AC27*AA27 | C27: =AI27*AG27 | D27: =W27*U27 | E27: =AK27*AM27 | F27: =AO27*AQ27 | G27: =AS27*AU27 | H27: =AW27*AY27 | I27: =BA27*BC27 | J27: =BE27*BG27 | K27: =BI27*BK27 | L27: =SUM(S27:U27,Y27:AA27,AE27:AG27,AK27,AO27,AS27,AW27,BA27,BE27,BI27)/($AE$16*$AE$16*3.15/10000*1000) | N27: 8
B28: =AC28*AA28 | C28: =AI28*AG28 | D28: =W28*U28 | E28: =AK28*AM28 | F28: =AO28*AQ28 | G28: =AS28*AU28 | H28: =AW28*AY28 | I28: =BA28*BC28 | J28: =BE28*BG28 | K28: =BI28*BK28 | L28: =SUM(S28:U28,Y28:AA28,AE28:AG28,AK28,AO28,AS28,AW28,BA28,BE28,BI28)/($AE$16*$AE$16*3.15/10000*1000) | N28: 9
B29: =AC29*AA29 | C29: =AI29*AG29 | D29: =W29*U29 | E29: =AK29*AM29 | F29: =AO29*AQ29 | G29: =AS29*AU29 | H29: =AW29*AY29 | I29: =BA29*BC29 | J29: =BE29*BG29 | K29: =BI29*BK29 | L29: =SUM(S29:U29,Y29:AA29,AE29:AG29,AK29,AO29,AS29,AW29,BA29,BE29,BI29)/($AE$16*$AE$16*3.15/10000*1000) | N29: 10
B30: =AC30*AA30 | C30: =AI30*AG30 | D30: =W30*U30 | E30: =AK30*AM30 | F30: =AO30*AQ30 | G30: =AS30*AU30 | H30: =AW30*AY30 | I30: =BA30*BC30 | J30: =BE30*BG30 | K30: =BI30*BK30 | L30: =SUM(S30:U30,Y30:AA30,AE30:AG30,AK30,AO30,AS30,AW30,BA30,BE30,BI30)/($AE$16*$AE$16*3.15/10000*1000) | N30: 11
B31: =AC31*AA31 | C31: =AI31*AG31 | D31: =W31*U31 | E31: =AK31*AM31 | F31: =AO31*AQ31 | G31: =AS31*AU31 | H31: =AW31*AY31 | I31: =BA31*BC31 | J31: =BE31*BG31 | K31: =BI31*BK31 | L31: =SUM(S31:U31,Y31:AA31,AE31:AG31,AK31,AO31,AS31,AW31,BA31,BE31,BI31)/($AE$16*$AE$16*3.15/10000*1000) | N31: 12
B32: =AC32*AA32 | C32: =AI32*AG32 | D32: =W32*U32 | E32: =AK32*AM32 | F32: =AO32*AQ32 | G32: =AS32*AU32 | H32: =AW32*AY32 | I32: =BA32*BC32 | J32: =BE32*BG32 | K32: =BI32*BK32 | L32: =SUM(S32:U32,Y32:AA32,AE32:AG32,AK32,AO32,AS32,AW32,BA32,BE32,BI32)/($AE$16*$AE$16*3.15/10000*1000) | N32: 13
B33: =AC33*AA33 | C33: =AI33*AG33 | D33: =W33*U33 | E33: =AK33*AM33 | F33: =AO33*AQ33 | G33: =AS33*AU33 | H33: =AW33*AY33 | I33: =BA33*BC33 | J33: =BE33*BG33 | K33: =BI33*BK33 | L33: =SUM(S33:U33,Y33:AA33,AE33:AG33,AK33,AO33,AS33,AW33,BA33,BE33,BI33)/($AE$16*$AE$16*3.15/10000*1000) | N33: 14
B34: =AC34*AA34 | C34: =AI34*AG34 | D34: =W34*U34 | E34: =AK34*AM34 | F34: =AO34*AQ34 | G34: =AS34*AU34 | H34: =AW34*AY34 | I34: =BA34*BC34 | J34: =BE34*BG34 | K34: =BI34*BK34 | L34: =SUM(S34:U34,Y34:AA34,AE34:AG34,AK34,AO34,AS34,AW34,BA34,BE34,BI34)/($AE$16*$AE$16*3.15/10000*1000) | N34: 15
B35: =AC35*AA35 | C35: =AI35*AG35 | D35: =W35*U35 | E35: =AK35*AM35 | F35: =AO35*AQ35 | G35: =AS35*AU35 | H35: =AW35*AY35 | I35: =BA35*BC35 | J35: =BE35*BG35 | K35: =BI35*BK35 | L35: =SUM(S35:U35,Y35:AA35,AE35:AG35,AK35,AO35,AS35,AW35,BA35,BE35,BI35)/($AE$16*$AE$16*3.15/10000*1000) | N35: 16
... B51: =AC51*AA51 | C51: =AI51*AG51 | D51: =W51*U51 | E51: =AK51*AM51 | F51: =AO51*AQ51 | G51: =AS51*AU51 | H51: =AW51*AY51 | I51: =BA51*BC51 | J51: =BE51*BG51 | K51: =BI51*BK51 | L51: =SUM(S51:U51,Y51:AA51,AE51:AG51,AK51,AO51,AS51,AW51,BA51,BE51,BI51)/($AE$16*$AE$16*3.15/10000*1000) | N51: 32
N52: Среднее | S52: =AVERAGE(S20:S51) | T52: =AVERAGE(T20:T51) | U52: =AVERAGE(U20:U51) | V52: =AVERAGE(V20:V51) | W52: =(SUM(D20:D51)+SUM(T20:T51)+SUM(S20:S51)*0.35)/SUM(S20:U51) | X52: =AVERAGE(X20:X51) | Y52: =AVERAGE(Y20:Y51) | Z52: =AVERAGE(Z20:Z51) | AA52: =AVERAGE(AA20:AA51) | AB52: =AVERAGE(AB20:AB51) | AC52: =(SUM(B20:B51)+SUM(Z20:Z51)+SUM(Y20:Y51)*0.35)/SUM(Y20:AA51) | AD52: =AVERAGE(AD20:AD51) | AE52: =AVERAGE(AE20:AE51) | AF52: =AVERAGE(AF20:AF51) | AG52: =AVERAGE(AG20:AG51) | AH52: =AVERAGE(AH20:AH51) | AI52: =(SUM(C20:C51)+SUM(AF20:AF51)+SUM(AE20:AE51)*0.35)/SUM(AE20:AG51) | AJ52: =AVERAGE(AJ20:AJ51) | AK52: =AVERAGE(AK20:AK51) | AL52: =AVERAGE(AL20:AL51) | AM52: =SUM(E20:E51)/SUM(AK20:AK51) | AN52: =AVERAGE(AN20:AN51) | AO52: =AVERAGE(AO20:AO51) | AP52: =AVERAGE(AP20:AP51) | AQ52: =SUM(F20:F51)/SUM(AO20:AO51) | AR52: =AVERAGE(AR20:AR51) | AS52: =AVERAGE(AS20:AS51) | AT52: =AVERAGE(AT20:AT51) | AU52: =SUM(G20:G51)/SUM(AS20:AS51) | AV52: =AVERAGE(AV20:AV51) | AW52: =AVERAGE(AW20:AW51) | AX52: =AVERAGE(AX20:AX51) | AY52: =SUM(H20:H51)/SUM(AW20:AW51) | AZ52: =AVERAGE(AZ20:AZ51) | BA52: =AVERAGE(BA20:BA51) | BB52: =AVERAGE(BB20:BB51) | BC52: =SUM(I20:I51)/SUM(BA20:BA51) | BD52: =AVERAGE(BD20:BD51) | BE52: =AVERAGE(BE20:BE51) | BF52: =AVERAGE(BF20:BF51) | BG52: =SUM(J20:J51)/SUM(BE20:BE51) | BH52: =AVERAGE(BH20:BH51) | BI52: =AVERAGE(BI20:BI51) | BJ52: =AVERAGE(BJ20:BJ51) | BK52: =SUM(K20:K51)/SUM(BI20:BI51) | BL52: =AVERAGE(BL20:BL51)
N53: H выше 1.5 | W53: =SUM(D20:D51)/SUM(U20:U51) | AC53: =SUM(B20:B51)/SUM(AA20:AA51) | AI53: =SUM(C20:C51)/SUM(AG20:AG51)
N54: D
N55: A
U60: =T13 | V60: Рубки
B61: Костыль для итоговых значений | O61: Итоговая характеристика насаждения
B62: =V62 | C62: =W62 | D62: =X62 | U62: Густота | V62: =AB19 | W62: =AC19 | X62: =AD19
B63: =V63*U63 | C63: =W63*U63 | D63: =X63*U63 | O63: =U63/$U$75*10 | R63: =S18 | U63: =SUM(S52:U52)/(AE16*AE16*3.15/10000*1000) | V63: =V52 | W63: =W52 | X63: =X52
B64: =V64*U64 | C64: =W64*U64 | D64: =X64*U64 | O64: =U64/$U$75*10 | R64: =Y18 | U64: =SUM(Y52:AA52)/(AE16*AE16*3.15/10000*1000) | V64: =AB52 | W64: =AC52 | X64: =AD52
B65: =V65*U65 | C65: =W65*U65 | D65: =X65*U65 | O65: =U65/$U$75*10 | R65: =AE18 | U65: =SUM(AE52:AG52)/(AE16*AE16*3.15/10000*1000) | V65: =AH52 | W65: =AI52 | X65: =AJ52
B66: =V66*U66 | C66: =W66*U66 | D66: =X66*U66 | O66: =U66/$U$75*10 | R66: =AK18 | U66: =AK52/(AE16*AE16*3.15/10000*1000) | V66: =AL52 | W66: =AM52 | X66: =AN52
...

Sheet До рубки 183 в 17(осв) 
W2: ИНСТРУКЦИЯ | AE2: 8 | AF2: Скопировать итоговые характеристики насаждения "До" и "После" в лист "Расчёты для проекта"
V3: 1 | W3: Скопировать лист внутри книги Excel | AE3: 9 | AF3: Заполнить Проект рубок ухода
V4: 2 | W4: Указать стадию (переименовать лист) "До рубки" | AE4: 10 | AF4: Скопировать данные перечёта по породам в Перечётные ведомости
V5: 3 | W5: Заполнит информацию о делянке (номер ведомости, квартал, выдел и т.д.) | AE5: 11 | AF5: Оформить пакет сопроводительной документация на делянку
V6: 4 | W6: Ввести данные перечёта | AE6: 12 | AF6: Подать уведомление в лесничество
V7: 5 | W7: Скопировать лист "до рубки" внутри книги Excel | AE7: 13 | AF7: Провести рубку
V8: 6 | W8: Указать стадию (переименовать лист) "После рубки" | AE8: 14
V9: 7 | W9: Удалить из ведомости перечёта то, что проектируется удалить в натуре | AE9: 15
N13: Стадия (до, проект или после рубки)
N16: Перечётная ведомость | S16: 1 | U16: Кв | V16: 183 | X16: Выд | Y16: 17 | Z16: делянка | AA16: 2 | AC16: Радиус ПП, м | AE16: 1.78 | AG16: Измерения выполнил: __________________ Дата, подпись, расшифровка _________________________
B18: Костыль для высоты | N18: Пор. | O18: Площадка | S18: Сосна | Y18: Ель из подроста | AE18: ЕЛЬ лесные культуры | AK18: Берёза | AO18: Осина | AS18: Ольха серая | AW18: Ива | BA18: Чёрёмуха | BE18: Дуб | BI18: Рябина
B19: =Y18 | C19: =AE18 | D19: =S18 | E19: =AK18 | F19: =AO18 | G19: =AS18 | H19: =AW18 | I19: =BA18 | J19: =BE18 | K19: =BI18 | L19: Всего, тыс.шт/га | N19: NN | O19: GPS точка | P19: ТЛ/ТУМ | Q19: Предмет ухода | R19: примечание | S19: До 0.5м | T19: 0,5-1,5 | U19: > 1.5 | V19: D, см | W19: h, м | X19: A, лет | Y19: До 0.5м | Z19: 0,5-1,5 | AA19: > 1.5 | AB19: D, см | AC19: h, м | AD19: A, лет | AE19: До 0.5м | AF19: 0,5-1,5 | AG19: > 1.5 | AH19: D, см | AI19: h, м | AJ19: A, лет | AK19: Кол-во | AL19: D, см | AM19: h, м | AN19: A, лет | AO19: Кол-во | AP19: D, см | AQ19: h, м | AR19: A, лет | AS19: Кол-во | AT19: D, см | AU19: h, м | AV19: A, лет | AW19: Кол-во | AX19: D, см | AY19: h, м | AZ19: A, лет | BA19: Кол-во | BB19: D, см | BC19: h, м | BD19: A, лет | BE19: Кол-во | BF19: D, см | BG19: h, м | BH19: A, лет | BI19: Кол-во | BJ19: D, см | BK19: h, м | BL19: A, лет
B20: =AC20*AA20 | C20: =AI20*AG20 | D20: =W20*U20 | E20: =AK20*AM20 | F20: =AO20*AQ20 | G20: =AS20*AU20 | H20: =AW20*AY20 | I20: =BA20*BC20 | J20: =BE20*BG20 | K20: =BI20*BK20 | L20: =SUM(S20:U20,Y20:AA20,AE20:AG20,AK20,AO20,AS20,AW20,BA20,BE20,BI20)/($AE$16*$AE$16*3.15/10000*1000) | N20: 1 | O20: 913 | P20: БР/В2 | S20: 1e-06 | T20: 1e-06 | U20: 1e-06 | Y20: 1 | Z20: 1e-06 | AA20: 1 | AC20: 1.8 | AD20: 9 | AE20: 1e-06 | AF20: 1e-06 | AG20: 1e-06 | AK20: 10 | AM20: 2.5 | AN20: 9 | AO20: 1e-06 | AS20: 1e-06 | AW20: 1e-06 | BA20: 1e-06 | BE20: 1e-06 | BI20: 1e-06
B21: =AC21*AA21 | C21: =AI21*AG21 | D21: =W21*U21 | E21: =AK21*AM21 | F21: =AO21*AQ21 | G21: =AS21*AU21 | H21: =AW21*AY21 | I21: =BA21*BC21 | J21: =BE21*BG21 | K21: =BI21*BK21 | L21: =SUM(S21:U21,Y21:AA21,AE21:AG21,AK21,AO21,AS21,AW21,BA21,BE21,BI21)/($AE$16*$AE$16*3.15/10000*1000) | N21: 2 | O21: 908 | P21: БР/В2 | Y21: 0 | Z21: 0 | AA21: 0 | AK21: 15 | AM21: 1.3 | AN21: 7 | AO21: 2 | AQ21: 1.7 | AR21: 7 | AS21: 4 | AU21: 1.2 | AV21: 7
B22: =AC22*AA22 | C22: =AI22*AG22 | D22: =W22*U22 | E22: =AK22*AM22 | F22: =AO22*AQ22 | G22: =AS22*AU22 | H22: =AW22*AY22 | I22: =BA22*BC22 | J22: =BE22*BG22 | K22: =BI22*BK22 | L22: =SUM(S22:U22,Y22:AA22,AE22:AG22,AK22,AO22,AS22,AW22,BA22,BE22,BI22)/($AE$16*$AE$16*3.15/10000*1000) | N22: 3 | O22: 909 | P22: БР/В2 | Y22: 1 | Z22: 2 | AA22: 0 | AD22: 8 | AK22: 1 | AM22: 1.7 | AN22: 8 | AO22: 1 | AQ22: 1.7 | AR22: 8 | AS22: 0
B23: =AC23*AA23 | C23: =AI23*AG23 | D23: =W23*U23 | E23: =AK23*AM23 | F23: =AO23*AQ23 | G23: =AS23*AU23 | H23: =AW23*AY23 | I23: =BA23*BC23 | J23: =BE23*BG23 | K23: =BI23*BK23 | L23: =SUM(S23:U23,Y23:AA23,AE23:AG23,AK23,AO23,AS23,AW23,BA23,BE23,BI23)/($AE$16*$AE$16*3.15/10000*1000) | N23: 4 | O23: 910 | P23: С/A5 | R23: Вол/Пас | Y23: 0 | Z23: 3 | AA23: 1 | AC23: 1.9 | AD23: 8 | AK23: 7 | AM23: 2.3 | AN23: 8 | AO23: 2 | AQ23: 1.2 | AR23: 7 | AS23: 0
B24: =AC24*AA24 | C24: =AI24*AG24 | D24: =W24*U24 | E24: =AK24*AM24 | F24: =AO24*AQ24 | G24: =AS24*AU24 | H24: =AW24*AY24 | I24: =BA24*BC24 | J24: =BE24*BG24 | K24: =BI24*BK24 | L24: =SUM(S24:U24,Y24:AA24,AE24:AG24,AK24,AO24,AS24,AW24,BA24,BE24,BI24)/($AE$16*$AE$16*3.15/10000*1000) | N24: 5 | O24: 911 | P24: С/A5 | Y24: 1 | Z24: 5 | AA24: 0 | AD24: 7 | AK24: 8 | AM24: 1.9 | AN24: 8 | AO24: 0 | AS24: 0
B25: =AC25*AA25 | C25: =AI25*AG25 | D25: =W25*U25 | E25: =AK25*AM25 | F25: =AO25*AQ25 | G25: =AS25*AU25 | H25: =AW25*AY25 | I25: =BA25*BC25 | J25: =BE25*BG25 | K25: =BI25*BK25 | L25: =SUM(S25:U25,Y25:AA25,AE25:AG25,AK25,AO25,AS25,AW25,BA25,BE25,BI25)/($AE$16*$AE$16*3.15/10000*1000) | N25: 6 | O25: 912 | P25: БР/В2 | R25: Пасека | Y25: 2 | Z25: 4 | AA25: 0 | AD25: 8 | AK25: 22 | AM25: 3.2 | AN25: 8 | AO25: 0 | AS25: 0
B26: =AC26*AA26 | C26: =AI26*AG26 | D26: =W26*U26 | E26: =AK26*AM26 | F26: =AO26*AQ26 | G26: =AS26*AU26 | H26: =AW26*AY26 | I26: =BA26*BC26 | J26: =BE26*BG26 | K26: =BI26*BK26 | L26: =SUM(S26:U26,Y26:AA26,AE26:AG26,AK26,AO26,AS26,AW26,BA26,BE26,BI26)/($AE$16*$AE$16*3.15/10000*1000) | N26: 7
B27: =AC27*AA27 | C27: =AI27*AG27 | D27: =W27*U27 | E27: =AK27*AM27 | F27: =AO27*AQ27 | G27: =AS27*AU27 | H27: =AW27*AY27 | I27: =BA27*BC27 | J27: =BE27*BG27 | K27: =BI27*BK27 | L27: =SUM(S27:U27,Y27:AA27,AE27:AG27,AK27,AO27,AS27,AW27,BA27,BE27,BI27)/($AE$16*$AE$16*3.15/10000*1000) | N27: 8
B28: =AC28*AA28 | C28: =AI28*AG28 | D28: =W28*U28 | E28: =AK28*AM28 | F28: =AO28*AQ28 | G28: =AS28*AU28 | H28: =AW28*AY28 | I28: =BA28*BC28 | J28: =BE28*BG28 | K28: =BI28*BK28 | L28: =SUM(S28:U28,Y28:AA28,AE28:AG28,AK28,AO28,AS28,AW28,BA28,BE28,BI28)/($AE$16*$AE$16*3.15/10000*1000) | N28: 9
B29: =AC29*AA29 | C29: =AI29*AG29 | D29: =W29*U29 | E29: =AK29*AM29 | F29: =AO29*AQ29 | G29: =AS29*AU29 | H29: =AW29*AY29 | I29: =BA29*BC29 | J29: =BE29*BG29 | K29: =BI29*BK29 | L29: =SUM(S29:U29,Y29:AA29,AE29:AG29,AK29,AO29,AS29,AW29,BA29,BE29,BI29)/($AE$16*$AE$16*3.15/10000*1000) | N29: 10
B30: =AC30*AA30 | C30: =AI30*AG30 | D30: =W30*U30 | E30: =AK30*AM30 | F30: =AO30*AQ30 | G30: =AS30*AU30 | H30: =AW30*AY30 | I30: =BA30*BC30 | J30: =BE30*BG30 | K30: =BI30*BK30 | L30: =SUM(S30:U30,Y30:AA30,AE30:AG30,AK30,AO30,AS30,AW30,BA30,BE30,BI30)/($AE$16*$AE$16*3.15/10000*1000) | N30: 11
B31: =AC31*AA31 | C31: =AI31*AG31 | D31: =W31*U31 | E31: =AK31*AM31 | F31: =AO31*AQ31 | G31: =AS31*AU31 | H31: =AW31*AY31 | I31: =BA31*BC31 | J31: =BE31*BG31 | K31: =BI31*BK31 | L31: =SUM(S31:U31,Y31:AA31,AE31:AG31,AK31,AO31,AS31,AW31,BA31,BE31,BI31)/($AE$16*$AE$16*3.15/10000*1000) | N31: 12
B32: =AC32*AA32 | C32: =AI32*AG32 | D32: =W32*U32 | E32: =AK32*AM32 | F32: =AO32*AQ32 | G32: =AS32*AU32 | H32: =AW32*AY32 | I32: =BA32*BC32 | J32: =BE32*BG32 | K32: =BI32*BK32 | L32: =SUM(S32:U32,Y32:AA32,AE32:AG32,AK32,AO32,AS32,AW32,BA32,BE32,BI32)/($AE$16*$AE$16*3.15/10000*1000) | N32: 13
B33: =AC33*AA33 | C33: =AI33*AG33 | D33: =W33*U33 | E33: =AK33*AM33 | F33: =AO33*AQ33 | G33: =AS33*AU33 | H33: =AW33*AY33 | I33: =BA33*BC33 | J33: =BE33*BG33 | K33: =BI33*BK33 | L33: =SUM(S33:U33,Y33:AA33,AE33:AG33,AK33,AO33,AS33,AW33,BA33,BE33,BI33)/($AE$16*$AE$16*3.15/10000*1000) | N33: 14
B34: =AC34*AA34 | C34: =AI34*AG34 | D34: =W34*U34 | E34: =AK34*AM34 | F34: =AO34*AQ34 | G34: =AS34*AU34 | H34: =AW34*AY34 | I34: =BA34*BC34 | J34: =BE34*BG34 | K34: =BI34*BK34 | L34: =SUM(S34:U34,Y34:AA34,AE34:AG34,AK34,AO34,AS34,AW34,BA34,BE34,BI34)/($AE$16*$AE$16*3.15/10000*1000) | N34: 15
B35: =AC35*AA35 | C35: =AI35*AG35 | D35: =W35*U35 | E35: =AK35*AM35 | F35: =AO35*AQ35 | G35: =AS35*AU35 | H35: =AW35*AY35 | I35: =BA35*BC35 | J35: =BE35*BG35 | K35: =BI35*BK35 | L35: =SUM(S35:U35,Y35:AA35,AE35:AG35,AK35,AO35,AS35,AW35,BA35,BE35,BI35)/($AE$16*$AE$16*3.15/10000*1000) | N35: 16
B36: =AC36*AA36 | C36: =AI36*AG36 | D36: =W36*U36 | E36: =AK36*AM36 | F36: =AO36*AQ36 | G36: =AS36*AU36 | H36: =AW36*AY36 | I36: =BA36*BC36 | J36: =BE36*BG36 | K36: =BI36*BK36 | L36: =SUM(S36:U36,Y36:AA36,AE36:AG36,AK36,AO36,AS36,AW36,BA36,BE36,BI36)/($AE$16*$AE$16*3.15/10000*1000) | N36: 17
B37: =AC37*AA37 | C37: =AI37*AG37 | D37: =W37*U37 | E37: =AK37*AM37 | F37: =AO37*AQ37 | G37: =AS37*AU37 | H37: =AW37*AY37 | I37: =BA37*BC37 | J37: =BE37*BG37 | K37: =BI37*BK37 | L37: =SUM(S37:U37,Y37:AA37,AE37:AG37,AK37,AO37,AS37,AW37,BA37,BE37,BI37)/($AE$16*$AE$16*3.15/10000*1000) | N37: 18
... B51: =AC51*AA51 | C51: =AI51*AG51 | D51: =W51*U51 | E51: =AK51*AM51 | F51: =AO51*AQ51 | G51: =AS51*AU51 | H51: =AW51*AY51 | I51: =BA51*BC51 | J51: =BE51*BG51 | K51: =BI51*BK51 | L51: =SUM(S51:U51,Y51:AA51,AE51:AG51,AK51,AO51,AS51,AW51,BA51,BE51,BI51)/($AE$16*$AE$16*3.15/10000*1000) | N51: 32
N52: Среднее | S52: =AVERAGE(S20:S51) | T52: =AVERAGE(T20:T51) | U52: =AVERAGE(U20:U51) | V52: =AVERAGE(V20:V51) | W52: =(SUM(D20:D51)+SUM(T20:T51)+SUM(S20:S51)*0.35)/SUM(S20:U51) | X52: =AVERAGE(X20:X51) | Y52: =AVERAGE(Y20:Y51) | Z52: =AVERAGE(Z20:Z51) | AA52: =AVERAGE(AA20:AA51) | AB52: =AVERAGE(AB20:AB51) | AC52: =(SUM(B20:B51)+SUM(Z20:Z51)+SUM(Y20:Y51)*0.35)/SUM(Y20:AA51) | AD52: =AVERAGE(AD20:AD51) | AE52: =AVERAGE(AE20:AE51) | AF52: =AVERAGE(AF20:AF51) | AG52: =AVERAGE(AG20:AG51) | AH52: =AVERAGE(AH20:AH51) | AI52: =(SUM(C20:C51)+SUM(AF20:AF51)+SUM(AE20:AE51)*0.35)/SUM(AE20:AG51) | AJ52: =AVERAGE(AJ20:AJ51) | AK52: =AVERAGE(AK20:AK51) | AL52: =AVERAGE(AL20:AL51) | AM52: =SUM(E20:E51)/SUM(AK20:AK51) | AN52: =AVERAGE(AN20:AN51) | AO52: =AVERAGE(AO20:AO51) | AP52: =AVERAGE(AP20:AP51) | AQ52: =SUM(F20:F51)/SUM(AO20:AO51) | AR52: =AVERAGE(AR20:AR51) | AS52: =AVERAGE(AS20:AS51) | AT52: =AVERAGE(AT20:AT51) | AU52: =SUM(G20:G51)/SUM(AS20:AS51) | AV52: =AVERAGE(AV20:AV51) | AW52: =AVERAGE(AW20:AW51) | AX52: =AVERAGE(AX20:AX51) | AY52: =SUM(H20:H51)/SUM(AW20:AW51) | AZ52: =AVERAGE(AZ20:AZ51) | BA52: =AVERAGE(BA20:BA51) | BB52: =AVERAGE(BB20:BB51) | BC52: =SUM(I20:I51)/SUM(BA20:BA51) | BD52: =AVERAGE(BD20:BD51) | BE52: =AVERAGE(BE20:BE51) | BF52: =AVERAGE(BF20:BF51) | BG52: =SUM(J20:J51)/SUM(BE20:BE51) | BH52: =AVERAGE(BH20:BH51) | BI52: =AVERAGE(BI20:BI51) | BJ52: =AVERAGE(BJ20:BJ51) | BK52: =SUM(K20:K51)/SUM(BI20:BI51) | BL52: =AVERAGE(BL20:BL51)
N53: H выше 1.5 | W53: =SUM(D20:D51)/SUM(U20:U51) | AC53: =SUM(B20:B51)/SUM(AA20:AA51) | AI53: =SUM(C20:C51)/SUM(AG20:AG51)
N54: D
N55: A
U60: =T13 | V60: Рубки
B61: Костыль для итоговых значений | O61: Итоговая характеристика насаждения
B62: =V62 | C62: =W62 | D62: =X62 | U62: Густота | V62: =AB19 | W62: =AC19 | X62: =AD19
B63: =V63*U63 | C63: =W63*U63 | D63: =X63*U63 | O63: =U63/$U$75*10 | R63: =S18 | U63: =SUM(S52:U52)/(AE16*AE16*3.15/10000*1000) | V63: =V52 | W63: =W52 | X63: =X52
B64: =V64*U64 | C64: =W64*U64 | D64: =X64*U64 | O64: =U64/$U$75*10 | R64: =Y18 | U64: =SUM(Y52:AA52)/(AE16*AE16*3.15/10000*1000) | V64: =AB52 | W64: =AC52 | X64: =AD52
...

Sheet До рубки 174 в 17(осв)
W2: ИНСТРУКЦИЯ | AE2: 8 | AF2: Скопировать итоговые характеристики насаждения "До" и "После" в лист "Расчёты для проекта"
V3: 1 | W3: Скопировать лист внутри книги Excel | AE3: 9 | AF3: Заполнить Проект рубок ухода
V4: 2 | W4: Указать стадию (переименовать лист) "До рубки" | AE4: 10 | AF4: Скопировать данные перечёта по породам в Перечётные ведомости
V5: 3 | W5: Заполнит информацию о делянке (номер ведомости, квартал, выдел и т.д.) | AE5: 11 | AF5: Оформить пакет сопроводительной документация на делянку
V6: 4 | W6: Ввести данные перечёта | AE6: 12 | AF6: Подать уведомление в лесничество
V7: 5 | W7: Скопировать лист "до рубки" внутри книги Excel | AE7: 13 | AF7: Провести рубку
V8: 6 | W8: Указать стадию (переименовать лист) "После рубки" | AE8: 14
V9: 7 | W9: Удалить из ведомости перечёта то, что проектируется удалить в натуре | AE9: 15
N13: Стадия (до, проект или после рубки)
N16: Перечётная ведомость | S16: 1 | U16: Кв | V16: 174 | X16: Выд | Y16: 17 | Z16: делянка | AA16: 1 | AC16: Радиус ПП, м | AE16: 1.78 | AG16: Измерения выполнил: __________________ Дата, подпись, расшифровка _________________________
B18: Костыль для высоты | N18: Пор. | O18: Площадка | S18: Сосна | Y18: Ель из подроста | AE18: ЕЛЬ лесные культуры | AK18: Берёза | AO18: Осина | AS18: Ольха серая | AW18: Ива | BA18: Чёрёмуха | BE18: Дуб | BI18: Рябина
B19: =Y18 | C19: =AE18 | D19: =S18 | E19: =AK18 | F19: =AO18 | G19: =AS18 | H19: =AW18 | I19: =BA18 | J19: =BE18 | K19: =BI18 | L19: Всего, тыс.шт/га | N19: NN | O19: GPS точка | P19: ТЛ/ТУМ | Q19: Предмет ухода | R19: примечание | S19: До 0.5м | T19: 0,5-1,5 | U19: > 1.5 | V19: D, см | W19: h, м | X19: A, лет | Y19: До 0.5м | Z19: 0,5-1,5 | AA19: > 1.5 | AB19: D, см | AC19: h, м | AD19: A, лет | AE19: До 0.5м | AF19: 0,5-1,5 | AG19: > 1.5 | AH19: D, см | AI19: h, м | AJ19: A, лет | AK19: Кол-во | AL19: D, см | AM19: h, м | AN19: A, лет | AO19: Кол-во | AP19: D, см | AQ19: h, м | AR19: A, лет | AS19: Кол-во | AT19: D, см | AU19: h, м | AV19: A, лет | AW19: Кол-во | AX19: D, см | AY19: h, м | AZ19: A, лет | BA19: Кол-во | BB19: D, см | BC19: h, м | BD19: A, лет | BE19: Кол-во | BF19: D, см | BG19: h, м | BH19: A, лет | BI19: Кол-во | BJ19: D, см | BK19: h, м | BL19: A, лет
B20: =AC20*AA20 | C20: =AI20*AG20 | D20: =W20*U20 | E20: =AK20*AM20 | F20: =AO20*AQ20 | G20: =AS20*AU20 | H20: =AW20*AY20 | I20: =BA20*BC20 | J20: =BE20*BG20 | K20: =BI20*BK20 | L20: =SUM(S20:U20,Y20:AA20,AE20:AG20,AK20,AO20,AS20,AW20,BA20,BE20,BI20)/($AE$16*$AE$16*3.15/10000*1000) | N20: 1 | O20: 879 | P20: БР/А2 | Q20: 2Б1Е | S20: 1e-06 | T20: 1e-06 | U20: 1e-06 | Y20: 1e-06 | Z20: 1e-06 | AA20: 1e-06 | AE20: 1 | AF20: 2 | AG20: 1e-06 | AJ20: 9 | AK20: 9 | AM20: 2.3 | AN20: 9 | AO20: 19 | AQ20: 2.3 | AR20: 9 | AS20: 1e-06 | AW20: 1e-06 | BA20: 1e-06 | BE20: 1e-06 | BI20: 1e-06
B21: =AC21*AA21 | C21: =AI21*AG21 | D21: =W21*U21 | E21: =AK21*AM21 | F21: =AO21*AQ21 | G21: =AS21*AU21 | H21: =AW21*AY21 | I21: =BA21*BC21 | J21: =BE21*BG21 | K21: =BI21*BK21 | L21: =SUM(S21:U21,Y21:AA21,AE21:AG21,AK21,AO21,AS21,AW21,BA21,BE21,BI21)/($AE$16*$AE$16*3.15/10000*1000) | N21: 2 | O21: 880 | P21: БР/А2 | Q21: 2Б1Е | AE21: 4 | AF21: 6 | AJ21: 9 | AK21: 6 | AM21: 0.7 | AN21: 3 | AO21: 0 | AW21: 0
